Workbook

Sheet repasse
A1: UF | B1: GEO | C1: Emb. | D1: SKU | E1: QTD CX | F1: rota-ttv pre | G1: rota-ttv pos | H1: rota-delta ttv | I1: rota-ttc pos | J1: asr-ttv pre | K1: asr-ttv pos | L1: asr-delta ttv | M1: asr-ttc pos | N1: varejo-ttc pre | O1: varejo-ttc pos | P1: varejo-delta ttc | Q1: atacado-ttc pre | R1: atacado-ttc pos | S1: atacado-delta ttc
A2: AM | B2: GEO CO | C2: PET 200 | D2: GCA P200 | E2: =_xlfn.XLOOKUP($D2,depara_repasse!E:E,depara_repasse!K:K) -> 12 | F2: =ROUND(SUMIFS(repasse_ac!$R:$R,repasse_ac!$A:$A,$A2,repasse_ac!$F:$F,$D2,repasse_ac!$I:$I,"TTC PRÉ"),2) -> 1.71 | G2: =ROUND(SUMIFS(repasse_ac!$R:$R,repasse_ac!$A:$A,$A2,repasse_ac!$F:$F,$D2,repasse_ac!$I:$I,"TTC PÓS"),2) -> 1.71 | H2: =G2-F2 -> 0 | I2: =(ROUNDDOWN(ROUND(G2*(1+0.2),2)*100/10,0)*10+IF(MOD(ROUND(G2*(1+0.2),2)*100,10)>4,9,-1))/100 -> 2.09 | J2: =ROUND(SUMIFS(repasse_ac!$P:$P,repasse_ac!$A:$A,$A2,repasse_ac!$F:$F,$D2,repasse_ac!$I:$I,"TTC PRÉ"),2) -> 1.67 | K2: =ROUND(SUMIFS(repasse_ac!$P:$P,repasse_ac!$A:$A,$A2,repasse_ac!$F:$F,$D2,repasse_ac!$I:$I,"TTC PÓS"),2) -> 1.67 | L2: =K2-J2 -> 0 | M2: =(ROUNDDOWN(ROUND(K2*(1+0.2),2)*100/10,0)*10+IF(MOD(ROUND(K2*(1+0.2),2)*100,10)>4,9,-1))/100 -> 1.99 | N2: =ROUND(SUMIFS(repasse_ac!$J:$J,repasse_ac!$A:$A,$A2,repasse_ac!$F:$F,$D2,repasse_ac!$I:$I,"TTC PRÉ"),2) -> 1.99 | O2: =ROUND(SUMIFS(repasse_ac!$J:$J,repasse_ac!$A:$A,$A2,repasse_ac!$F:$F,$D2,repasse_ac!$I:$I,"TTC PÓS"),2) -> 1.99 | P2: =O2-N2 -> 0 | Q2: =ROUND(SUMIFS(repasse_ac!$N:$N,repasse_ac!$A:$A,$A2,repasse_ac!$F:$F,$D2,repasse_ac!$I:$I,"TTC PRÉ"),2) -> 1.89 | R2: =ROUND(SUMIFS(repasse_ac!$N:$N,repasse_ac!$A:$A,$A2,repasse_ac!$F:$F,$D2,repasse_ac!$I:$I,"TTC PÓS"),2) -> 1.89 | S2: =R2-Q2 -> 0
A3: AM | B3: GEO CO | C3: PET 200 | D3: GCAD P200 | E3: =_xlfn.XLOOKUP($D3,depara_repasse!E:E,depara_repasse!K:K) -> 12 | F3: =ROUND(SUMIFS(repasse_ac!$R:$R,repasse_ac!$A:$A,$A3,repasse_ac!$F:$F,$D3,repasse_ac!$I:$I,"TTC PRÉ"),2) -> 1.71 | G3: =ROUND(SUMIFS(repasse_ac!$R:$R,repasse_ac!$A:$A,$A3,repasse_ac!$F:$F,$D3,repasse_ac!$I:$I,"TTC PÓS"),2) -> 1.71 | H3: =G3-F3 -> 0 | I3: =(ROUNDDOWN(ROUND(G3*(1+0.2),2)*100/10,0)*10+IF(MOD(ROUND(G3*(1+0.2),2)*100,10)>4,9,-1))/100 -> 2.09 | J3: =ROUND(SUMIFS(repasse_ac!$P:$P,repasse_ac!$A:$A,$A3,repasse_ac!$F:$F,$D3,repasse_ac!$I:$I,"TTC PRÉ"),2) -> 1.67 | K3: =ROUND(SUMIFS(repasse_ac!$P:$P,repasse_ac!$A:$A,$A3,repasse_ac!$F:$F,$D3,repasse_ac!$I:$I,"TTC PÓS"),2) -> 1.67 | L3: =K3-J3 -> 0 | M3: =(ROUNDDOWN(ROUND(K3*(1+0.2),2)*100/10,0)*10+IF(MOD(ROUND(K3*(1+0.2),2)*100,10)>4,9,-1))/100 -> 1.99 | N3: =ROUND(SUMIFS(repasse_ac!$J:$J,repasse_ac!$A:$A,$A3,repasse_ac!$F:$F,$D3,repasse_ac!$I:$I,"TTC PRÉ"),2) -> 1.99 | O3: =ROUND(SUMIFS(repasse_ac!$J:$J,repasse_ac!$A:$A,$A3,repasse_ac!$F:$F,$D3,repasse_ac!$I:$I,"TTC PÓS"),2) -> 1.99 | P3: =O3-N3 -> 0 | Q3: =ROUND(SUMIFS(repasse_ac!$N:$N,repasse_ac!$A:$A,$A3,repasse_ac!$F:$F,$D3,repasse_ac!$I:$I,"TTC PRÉ"),2) -> 1.89 | R3: =ROUND(SUMIFS(repasse_ac!$N:$N,repasse_ac!$A:$A,$A3,repasse_ac!$F:$F,$D3,repasse_ac!$I:$I,"TTC PÓS"),2) -> 1.89 | S3: =R3-Q3 -> 0
A4: AM | B4: GEO CO | C4: PET 200 | D4: PC P200 | E4: =_xlfn.XLOOKUP($D4,depara_repasse!E:E,depara_repasse!K:K) -> 12 | F4: =ROUND(SUMIFS(repasse_ac!$R:$R,repasse_ac!$A:$A,$A4,repasse_ac!$F:$F,$D4,repasse_ac!$I:$I,"TTC PRÉ"),2) -> 1.62 | G4: =ROUND(SUMIFS(repasse_ac!$R:$R,repasse_ac!$A:$A,$A4,repasse_ac!$F:$F,$D4,repasse_ac!$I:$I,"TTC PÓS"),2) -> 1.71 | H4: =G4-F4 -> 0.09 | I4: =(ROUNDDOWN(ROUND(G4*(1+0.2),2)*100/10,0)*10+IF(MOD(ROUND(G4*(1+0.2),2)*100,10)>4,9,-1))/100 -> 2.09 | J4: =ROUND(SUMIFS(repasse_ac!$P:$P,repasse_ac!$A:$A,$A4,repasse_ac!$F:$F,$D4,repasse_ac!$I:$I,"TTC PRÉ"),2) -> 1.59 | K4: =ROUND(SUMIFS(repasse_ac!$P:$P,repasse_ac!$A:$A,$A4,repasse_ac!$F:$F,$D4,repasse_ac!$I:$I,"TTC PÓS"),2) -> 1.67 | L4: =K4-J4 -> 0.08 | M4: =(ROUNDDOWN(ROUND(K4*(1+0.2),2)*100/10,0)*10+IF(MOD(ROUND(K4*(1+0.2),2)*100,10)>4,9,-1))/100 -> 1.99 | N4: =ROUND(SUMIFS(repasse_ac!$J:$J,repasse_ac!$A:$A,$A4,repasse_ac!$F:$F,$D4,repasse_ac!$I:$I,"TTC PRÉ"),2) -> 1.89 | O4: =ROUND(SUMIFS(repasse_ac!$J:$J,repasse_ac!$A:$A,$A4,repasse_ac!$F:$F,$D4,repasse_ac!$I:$I,"TTC PÓS"),2) -> 1.99 | P4: =O4-N4 -> 0.1 | Q4: =ROUND(SUMIFS(repasse_ac!$N:$N,repasse_ac!$A:$A,$A4,repasse_ac!$F:$F,$D4,repasse_ac!$I:$I,"TTC PRÉ"),2) -> 1.79 | R4: =ROUND(SUMIFS(repasse_ac!$N:$N,repasse_ac!$A:$A,$A4,repasse_ac!$F:$F,$D4,repasse_ac!$I:$I,"TTC PÓS"),2) -> 1.89 | S4: =R4-Q4 -> 0.1
A5: AM | B5: GEO CO | C5: PET 200 | D5: SLA P200 | E5: =_xlfn.XLOOKUP($D5,depara_repasse!E:E,depara_repasse!K:K) -> 12 | F5: =ROUND(SUMIFS(repasse_ac!$R:$R,repasse_ac!$A:$A,$A5,repasse_ac!$F:$F,$D5,repasse_ac!$I:$I,"TTC PRÉ"),2) -> 1.62 | G5: =ROUND(SUMIFS(repasse_ac!$R:$R,repasse_ac!$A:$A,$A5,repasse_ac!$F:$F,$D5,repasse_ac!$I:$I,"TTC PÓS"),2) -> 1.71 | H5: =G5-F5 -> 0.09 | I5: =(ROUNDDOWN(ROUND(G5*(1+0.2),2)*100/10,0)*10+IF(MOD(ROUND(G5*(1+0.2),2)*100,10)>4,9,-1))/100 -> 2.09 | J5: =ROUND(SUMIFS(repasse_ac!$P:$P,repasse_ac!$A:$A,$A5,repasse_ac!$F:$F,$D5,repasse_ac!$I:$I,"TTC PRÉ"),2) -> 1.59 | K5: =ROUND(SUMIFS(repasse_ac!$P:$P,repasse_ac!$A:$A,$A5,repasse_ac!$F:$F,$D5,repasse_ac!$I:$I,"TTC PÓS"),2) -> 1.67 | L5: =K5-J5 -> 0.08 | M5: =(ROUNDDOWN(ROUND(K5*(1+0.2),2)*100/10,0)*10+IF(MOD(ROUND(K5*(1+0.2),2)*100,10)>4,9,-1))/100 -> 1.99 | N5: =ROUND(SUMIFS(repasse_ac!$J:$J,repasse_ac!$A:$A,$A5,repasse_ac!$F:$F,$D5,repasse_ac!$I:$I,"TTC PRÉ"),2) -> 1.89 | O5: =ROUND(SUMIFS(repasse_ac!$J:$J,repasse_ac!$A:$A,$A5,repasse_ac!$F:$F,$D5,repasse_ac!$I:$I,"TTC PÓS"),2) -> 1.99 | P5: =O5-N5 -> 0.1 | Q5: =ROUND(SUMIFS(repasse_ac!$N:$N,repasse_ac!$A:$A,$A5,repasse_ac!$F:$F,$D5,repasse_ac!$I:$I,"TTC PRÉ"),2) -> 1.79 | R5: =ROUND(SUMIFS(repasse_ac!$N:$N,repasse_ac!$A:$A,$A5,repasse_ac!$F:$F,$D5,repasse_ac!$I:$I,"TTC PÓS"),2) -> 1.89 | S5: =R5-Q5 -> 0.1
A6: AM | B6: GEO CO | C6: PET 200 | D6: SAB P200 | E6: =_xlfn.XLOOKUP($D6,depara_repasse!E:E,depara_repasse!K:K) -> 12 | F6: =ROUND(SUMIFS(repasse_ac!$R:$R,repasse_ac!$A:$A,$A6,repasse_ac!$F:$F,$D6,repasse_ac!$I:$I,"TTC PRÉ"),2) -> 1.62 | G6: =ROUND(SUMIFS(repasse_ac!$R:$R,repasse_ac!$A:$A,$A6,repasse_ac!$F:$F,$D6,repasse_ac!$I:$I,"TTC PÓS"),2) -> 1.71 | H6: =G6-F6 -> 0.09 | I6: =(ROUNDDOWN(ROUND(G6*(1+0.2),2)*100/10,0)*10+IF(MOD(ROUND(G6*(1+0.2),2)*100,10)>4,9,-1))/100 -> 2.09 | J6: =ROUND(SUMIFS(repasse_ac!$P:$P,repasse_ac!$A:$A,$A6,repasse_ac!$F:$F,$D6,repasse_ac!$I:$I,"TTC PRÉ"),2) -> 1.59 | K6: =ROUND(SUMIFS(repasse_ac!$P:$P,repasse_ac!$A:$A,$A6,repasse_ac!$F:$F,$D6,repasse_ac!$I:$I,"TTC PÓS"),2) -> 1.67 | L6: =K6-J6 -> 0.08 | M6: =(ROUNDDOWN(ROUND(K6*(1+0.2),2)*100/10,0)*10+IF(MOD(ROUND(K6*(1+0.2),2)*100,10)>4,9,-1))/100 -> 1.99 | N6: =ROUND(SUMIFS(repasse_ac!$J:$J,repasse_ac!$A:$A,$A6,repasse_ac!$F:$F,$D6,repasse_ac!$I:$I,"TTC PRÉ"),2) -> 1.89 | O6: =ROUND(SUMIFS(repasse_ac!$J:$J,repasse_ac!$A:$A,$A6,repasse_ac!$F:$F,$D6,repasse_ac!$I:$I,"TTC PÓS"),2) -> 1.99 | P6: =O6-N6 -> 0.1 | Q6: =ROUND(SUMIFS(repasse_ac!$N:$N,repasse_ac!$A:$A,$A6,repasse_ac!$F:$F,$D6,repasse_ac!$I:$I,"TTC PRÉ"),2) -> 1.79 | R6: =ROUND(SUMIFS(repasse_ac!$N:$N,repasse_ac!$A:$A,$A6,repasse_ac!$F:$F,$D6,repasse_ac!$I:$I,"TTC PÓS"),2) -> 1.89 | S6: =R6-Q6 -> 0.1
A7: AM | B7: GEO CO | C7: LATA 269 | D7: GCA LT269 | E7: 15 | F7: =ROUND(SUMIFS(repasse_ac!$R:$R,repasse_ac!$A:$A,$A7,repasse_ac!$F:$F,$D7,repasse_ac!$I:$I,"TTC PRÉ"),2) -> 2.19 | G7: =ROUND(SUMIFS(repasse_ac!$R:$R,repasse_ac!$A:$A,$A7,repasse_ac!$F:$F,$D7,repasse_ac!$I:$I,"TTC PÓS"),2) -> 2.19 | H7: =G7-F7 -> 0 | I7: =(ROUNDDOWN(ROUND(G7*(1+0.2),2)*100/10,0)*10+IF(MOD(ROUND(G7*(1+0.2),2)*100,10)>4,9,-1))/100 -> 2.59 | J7: =ROUND(SUMIFS(repasse_ac!$P:$P,repasse_ac!$A:$A,$A7,repasse_ac!$F:$F,$D7,repasse_ac!$I:$I,"TTC PRÉ"),2) -> 2.09 | K7: =ROUND(SUMIFS(repasse_ac!$P:$P,repasse_ac!$A:$A,$A7,repasse_ac!$F:$F,$D7,repasse_ac!$I:$I,"TTC PÓS"),2) -> 2.09 | L7: =K7-J7 -> 0 | M7: =(ROUNDDOWN(ROUND(K7*(1+0.2),2)*100/10,0)*10+IF(MOD(ROUND(K7*(1+0.2),2)*100,10)>4,9,-1))/100 -> 2.49 | N7: =ROUND(SUMIFS(repasse_ac!$J:$J,repasse_ac!$A:$A,$A7,repasse_ac!$F:$F,$D7,repasse_ac!$I:$I,"TTC PRÉ"),2) -> 2.49 | O7: =ROUND(SUMIFS(repasse_ac!$J:$J,repasse_ac!$A:$A,$A7,repasse_ac!$F:$F,$D7,repasse_ac!$I:$I,"TTC PÓS"),2) -> 2.49 | P7: =O7-N7 -> 0 | Q7: =ROUND(SUMIFS(repasse_ac!$N:$N,repasse_ac!$A:$A,$A7,repasse_ac!$F:$F,$D7,repasse_ac!$I:$I,"TTC PRÉ"),2) -> 2.29 | R7: =ROUND(SUMIFS(repasse_ac!$N:$N,repasse_ac!$A:$A,$A7,repasse_ac!$F:$F,$D7,repasse_ac!$I:$I,"TTC PÓS"),2) -> 2.29 | S7: =R7-Q7 -> 0
A8: AM | B8: GEO CO | C8: LATA 269 | D8: PC LT269 | E8: =_xlfn.XLOOKUP($D8,depara_repasse!E:E,depara_repasse!K:K) -> 15 | F8: =ROUND(SUMIFS(repasse_ac!$R:$R,repasse_ac!$A:$A,$A8,repasse_ac!$F:$F,$D8,repasse_ac!$I:$I,"TTC PRÉ"),2) -> 2.19 | G8: =ROUND(SUMIFS(repasse_ac!$R:$R,repasse_ac!$A:$A,$A8,repasse_ac!$F:$F,$D8,repasse_ac!$I:$I,"TTC PÓS"),2) -> 2.19 | H8: =G8-F8 -> 0 | I8: =(ROUNDDOWN(ROUND(G8*(1+0.2),2)*100/10,0)*10+IF(MOD(ROUND(G8*(1+0.2),2)*100,10)>4,9,-1))/100 -> 2.59 | J8: =ROUND(SUMIFS(repasse_ac!$P:$P,repasse_ac!$A:$A,$A8,repasse_ac!$F:$F,$D8,repasse_ac!$I:$I,"TTC PRÉ"),2) -> 2.09 | K8: =ROUND(SUMIFS(repasse_ac!$P:$P,repasse_ac!$A:$A,$A8,repasse_ac!$F:$F,$D8,repasse_ac!$I:$I,"TTC PÓS"),2) -> 2.15 | L8: =K8-J8 -> 0.06 | M8: =(ROUNDDOWN(ROUND(K8*(1+0.2),2)*100/10,0)*10+IF(MOD(ROUND(K8*(1+0.2),2)*100,10)>4,9,-1))/100 -> 2.59 | N8: =ROUND(SUMIFS(repasse_ac!$J:$J,repasse_ac!$A:$A,$A8,repasse_ac!$F:$F,$D8,repasse_ac!$I:$I,"TTC PRÉ"),2) -> 2.49 | O8: =ROUND(SUMIFS(repasse_ac!$J:$J,repasse_ac!$A:$A,$A8,repasse_ac!$F:$F,$D8,repasse_ac!$I:$I,"TTC PÓS"),2) -> 2.59 | P8: =O8-N8 -> 0.1 | Q8: =ROUND(SUMIFS(repasse_ac!$N:$N,repasse_ac!$A:$A,$A8,repasse_ac!$F:$F,$D8,repasse_ac!$I:$I,"TTC PRÉ"),2) -> 2.29 | R8: =ROUND(SUMIFS(repasse_ac!$N:$N,repasse_ac!$A:$A,$A8,repasse_ac!$F:$F,$D8,repasse_ac!$I:$I,"TTC PÓS"),2) -> 2.29 | S8: =R8-Q8 -> 0
A9: AM | B9: GEO CO | C9: LATA 269 | D9: TA LT269 | E9: =_xlfn.XLOOKUP($D9,depara_repasse!E:E,depara_repasse!K:K) -> 15 | F9: =ROUND(SUMIFS(repasse_ac!$R:$R,repasse_ac!$A:$A,$A9,repasse_ac!$F:$F,$D9,repasse_ac!$I:$I,"TTC PRÉ"),2) -> 2.25 | G9: =ROUND(SUMIFS(repasse_ac!$R:$R,repasse_ac!$A:$A,$A9,repasse_ac!$F:$F,$D9,repasse_ac!$I:$I,"TTC PÓS"),2) -> 2.25 | H9: =G9-F9 -> 0 | I9: =(ROUNDDOWN(ROUND(G9*(1+0.2),2)*100/10,0)*10+IF(MOD(ROUND(G9*(1+0.2),2)*100,10)>4,9,-1))/100 -> 2.69 | J9: =ROUND(SUMIFS(repasse_ac!$P:$P,repasse_ac!$A:$A,$A9,repasse_ac!$F:$F,$D9,repasse_ac!$I:$I,"TTC PRÉ"),2) -> 2.09 | K9: =ROUND(SUMIFS(repasse_ac!$P:$P,repasse_ac!$A:$A,$A9,repasse_ac!$F:$F,$D9,repasse_ac!$I:$I,"TTC PÓS"),2) -> 2.17 | L9: =K9-J9 -> 0.08 | M9: =(ROUNDDOWN(ROUND(K9*(1+0.2),2)*100/10,0)*10+IF(MOD(ROUND(K9*(1+0.2),2)*100,10)>4,9,-1))/100 -> 2.59 | N9: =ROUND(SUMIFS(repasse_ac!$J:$J,repasse_ac!$A:$A,$A9,repasse_ac!$F:$F,$D9,repasse_ac!$I:$I,"TTC PRÉ"),2) -> 2.49 | O9: =ROUND(SUMIFS(repasse_ac!$J:$J,repasse_ac!$A:$A,$A9,repasse_ac!$F:$F,$D9,repasse_ac!$I:$I,"TTC PÓS"),2) -> 2.59 | P9: =O9-N9 -> 0.1 | Q9: =ROUND(SUMIFS(repasse_ac!$N:$N,repasse_ac!$A:$A,$A9,repasse_ac!$F:$F,$D9,repasse_ac!$I:$I,"TTC PRÉ"),2) -> 2.49 | R9: =ROUND(SUMIFS(repasse_ac!$N:$N,repasse_ac!$A:$A,$A9,repasse_ac!$F:$F,$D9,repasse_ac!$I:$I,"TTC PÓS"),2) -> 2.49 | S9: =R9-Q9 -> 0
A10: AM | B10: GEO CO | C10: LATA 310 | D10: GCA LT310 | E10: 12 | F10: =ROUND(SUMIFS(repasse_ac!$R:$R,repasse_ac!$A:$A,$A10,repasse_ac!$F:$F,$D10,repasse_ac!$I:$I,"TTC PRÉ"),2) -> 2.09 | G10: =ROUND(SUMIFS(repasse_ac!$R:$R,repasse_ac!$A:$A,$A10,repasse_ac!$F:$F,$D10,repasse_ac!$I:$I,"TTC PÓS"),2) -> 2.09 | H10: =G10-F10 -> 0 | I10: =(ROUNDDOWN(ROUND(G10*(1+0.2),2)*100/10,0)*10+IF(MOD(ROUND(G10*(1+0.2),2)*100,10)>4,9,-1))/100 -> 2.49 | J10: =ROUND(SUMIFS(repasse_ac!$P:$P,repasse_ac!$A:$A,$A10,repasse_ac!$F:$F,$D10,repasse_ac!$I:$I,"TTC PRÉ"),2) -> 1.92 | K10: =ROUND(SUMIFS(repasse_ac!$P:$P,repasse_ac!$A:$A,$A10,repasse_ac!$F:$F,$D10,repasse_ac!$I:$I,"TTC PÓS"),2) -> 1.92 | L10: =K10-J10 -> 0 | M10: =(ROUNDDOWN(ROUND(K10*(1+0.2),2)*100/10,0)*10+IF(MOD(ROUND(K10*(1+0.2),2)*100,10)>4,9,-1))/100 -> 2.39 | N10: =ROUND(SUMIFS(repasse_ac!$J:$J,repasse_ac!$A:$A,$A10,repasse_ac!$F:$F,$D10,repasse_ac!$I:$I,"TTC PRÉ"),2) -> 2.29 | O10: =ROUND(SUMIFS(repasse_ac!$J:$J,repasse_ac!$A:$A,$A10,repasse_ac!$F:$F,$D10,repasse_ac!$I:$I,"TTC PÓS"),2) -> 2.29 | P10: =O10-N10 -> 0 | Q10: =ROUND(SUMIFS(repasse_ac!$N:$N,repasse_ac!$A:$A,$A10,repasse_ac!$F:$F,$D10,repasse_ac!$I:$I,"TTC PRÉ"),2) -> 2.19 | R10: =ROUND(SUMIFS(repasse_ac!$N:$N,repasse_ac!$A:$A,$A10,repasse_ac!$F:$F,$D10,repasse_ac!$I:$I,"TTC PÓS"),2) -> 2.19 | S10: =R10-Q10 -> 0
A11: AM | B11: GEO CO | C11: LATA 310 | D11: PC LT310 | E11: =_xlfn.XLOOKUP($D11,depara_repasse!E:E,depara_repasse!K:K) -> 15 | F11: =ROUND(SUMIFS(repasse_ac!$R:$R,repasse_ac!$A:$A,$A11,repasse_ac!$F:$F,$D11,repasse_ac!$I:$I,"TTC PRÉ"),2) -> 2.09 | G11: =ROUND(SUMIFS(repasse_ac!$R:$R,repasse_ac!$A:$A,$A11,repasse_ac!$F:$F,$D11,repasse_ac!$I:$I,"TTC PÓS"),2) -> 2.09 | H11: =G11-F11 -> 0 | I11: =(ROUNDDOWN(ROUND(G11*(1+0.2),2)*100/10,0)*10+IF(MOD(ROUND(G11*(1+0.2),2)*100,10)>4,9,-1))/100 -> 2.49 | J11: =ROUND(SUMIFS(repasse_ac!$P:$P,repasse_ac!$A:$A,$A11,repasse_ac!$F:$F,$D11,repasse_ac!$I:$I,"TTC PRÉ"),2) -> 1.92 | K11: =ROUND(SUMIFS(repasse_ac!$P:$P,repasse_ac!$A:$A,$A11,repasse_ac!$F:$F,$D11,repasse_ac!$I:$I,"TTC PÓS"),2) -> 1.92 | L11: =K11-J11 -> 0 | M11: =(ROUNDDOWN(ROUND(K11*(1+0.2),2)*100/10,0)*10+IF(MOD(ROUND(K11*(1+0.2),2)*100,10)>4,9,-1))/100 -> 2.39 | N11: =ROUND(SUMIFS(repasse_ac!$J:$J,repasse_ac!$A:$A,$A11,repasse_ac!$F:$F,$D11,repasse_ac!$I:$I,"TTC PRÉ"),2) -> 2.29 | O11: =ROUND(SUMIFS(repasse_ac!$J:$J,repasse_ac!$A:$A,$A11,repasse_ac!$F:$F,$D11,repasse_ac!$I:$I,"TTC PÓS"),2) -> 2.29 | P11: =O11-N11 -> 0 | Q11: =ROUND(SUMIFS(repasse_ac!$N:$N,repasse_ac!$A:$A,$A11,repasse_ac!$F:$F,$D11,repasse_ac!$I:$I,"TTC PRÉ"),2) -> 2.19 | R11: =ROUND(SUMIFS(repasse_ac!$N:$N,repasse_ac!$A:$A,$A11,repasse_ac!$F:$F,$D11,repasse_ac!$I:$I,"TTC PÓS"),2) -> 2.19 | S11: =R11-Q11 -> 0
A12: AM | B12: GEO CO | C12: LATA 350 | D12: GCA LT350 | E12: =_xlfn.XLOOKUP($D12,depara_repasse!E:E,depara_repasse!K:K) -> 12 | F12: =ROUND(SUMIFS(repasse_ac!$R:$R,repasse_ac!$A:$A,$A12,repasse_ac!$F:$F,$D12,repasse_ac!$I:$I,"TTC PRÉ"),2) -> 3.06 | G12: =ROUND(SUMIFS(repasse_ac!$R:$R,repasse_ac!$A:$A,$A12,repasse_ac!$F:$F,$D12,repasse_ac!$I:$I,"TTC PÓS"),2) -> 3.06 | H12: =G12-F12 -> 0 | I12: =(ROUNDDOWN(ROUND(G12*(1+0.2),2)*100/10,0)*10+IF(MOD(ROUND(G12*(1+0.2),2)*100,10)>4,9,-1))/100 -> 3.69 | J12: =ROUND(SUMIFS(repasse_ac!$P:$P,repasse_ac!$A:$A,$A12,repasse_ac!$F:$F,$D12,repasse_ac!$I:$I,"TTC PRÉ"),2) -> 2.92 | K12: =ROUND(SUMIFS(repasse_ac!$P:$P,repasse_ac!$A:$A,$A12,repasse_ac!$F:$F,$D12,repasse_ac!$I:$I,"TTC PÓS"),2) -> 2.92 | L12: =K12-J12 -> 0 | M12: =(ROUNDDOWN(ROUND(K12*(1+0.2),2)*100/10,0)*10+IF(MOD(ROUND(K12*(1+0.2),2)*100,10)>4,9,-1))/100 -> 3.49 | N12: =ROUND(SUMIFS(repasse_ac!$J:$J,repasse_ac!$A:$A,$A12,repasse_ac!$F:$F,$D12,repasse_ac!$I:$I,"TTC PRÉ"),2) -> 3.49 | O12: =ROUND(SUMIFS(repasse_ac!$J:$J,repasse_ac!$A:$A,$A12,repasse_ac!$F:$F,$D12,repasse_ac!$I:$I,"TTC PÓS"),2) -> 3.49 | P12: =O12-N12 -> 0 | Q12: =ROUND(SUMIFS(repasse_ac!$N:$N,repasse_ac!$A:$A,$A12,repasse_ac!$F:$F,$D12,repasse_ac!$I:$I,"TTC PRÉ"),2) -> 3.39 | R12: =ROUND(SUMIFS(repasse_ac!$N:$N,repasse_ac!$A:$A,$A12,repasse_ac!$F:$F,$D12,repasse_ac!$I:$I,"TTC PÓS"),2) -> 3.39 | S12: =R12-Q12 -> 0
A13: AM | B13: GEO CO | C13: LATA 350 | D13: GCAD LT350 | E13: =_xlfn.XLOOKUP($D13,depara_repasse!E:E,depara_repasse!K:K) -> 12 | F13: =ROUND(SUMIFS(repasse_ac!$R:$R,repasse_ac!$A:$A,$A13,repasse_ac!$F:$F,$D13,repasse_ac!$I:$I,"TTC PRÉ"),2) -> 3.06 | G13: =ROUND(SUMIFS(repasse_ac!$R:$R,repasse_ac!$A:$A,$A13,repasse_ac!$F:$F,$D13,repasse_ac!$I:$I,"TTC PÓS"),2) -> 3.06 | H13: =G13-F13 -> 0 | I13: =(ROUNDDOWN(ROUND(G13*(1+0.2),2)*100/10,0)*10+IF(MOD(ROUND(G13*(1+0.2),2)*100,10)>4,9,-1))/100 -> 3.69 | J13: =ROUND(SUMIFS(repasse_ac!$P:$P,repasse_ac!$A:$A,$A13,repasse_ac!$F:$F,$D13,repasse_ac!$I:$I,"TTC PRÉ"),2) -> 2.92 | K13: =ROUND(SUMIFS(repasse_ac!$P:$P,repasse_ac!$A:$A,$A13,repasse_ac!$F:$F,$D13,repasse_ac!$I:$I,"TTC PÓS"),2) -> 2.92 | L13: =K13-J13 -> 0 | M13: =(ROUNDDOWN(ROUND(K13*(1+0.2),2)*100/10,0)*10+IF(MOD(ROUND(K13*(1+0.2),2)*100,10)>4,9,-1))/100 -> 3.49 | N13: =ROUND(SUMIFS(repasse_ac!$J:$J,repasse_ac!$A:$A,$A13,repasse_ac!$F:$F,$D13,repasse_ac!$I:$I,"TTC PRÉ"),2) -> 3.49 | O13: =ROUND(SUMIFS(repasse_ac!$J:$J,repasse_ac!$A:$A,$A13,repasse_ac!$F:$F,$D13,repasse_ac!$I:$I,"TTC PÓS"),2) -> 3.49 | P13: =O13-N13 -> 0 | Q13: =ROUND(SUMIFS(repasse_ac!$N:$N,repasse_ac!$A:$A,$A13,repasse_ac!$F:$F,$D13,repasse_ac!$I:$I,"TTC PRÉ"),2) -> 3.39 | R13: =ROUND(SUMIFS(repasse_ac!$N:$N,repasse_ac!$A:$A,$A13,repasse_ac!$F:$F,$D13,repasse_ac!$I:$I,"TTC PÓS"),2) -> 3.39 | S13: =R13-Q13 -> 0
A14: AM | B14: GEO CO | C14: LATA 350 | D14: PC LT350 | E14: =_xlfn.XLOOKUP($D14,depara_repasse!E:E,depara_repasse!K:K) -> 12 | F14: =ROUND(SUMIFS(repasse_ac!$R:$R,repasse_ac!$A:$A,$A14,repasse_ac!$F:$F,$D14,repasse_ac!$I:$I,"TTC PRÉ"),2) -> 2.96 | G14: =ROUND(SUMIFS(repasse_ac!$R:$R,repasse_ac!$A:$A,$A14,repasse_ac!$F:$F,$D14,repasse_ac!$I:$I,"TTC PÓS"),2) -> 2.96 | H14: =G14-F14 -> 0 | I14: =(ROUNDDOWN(ROUND(G14*(1+0.2),2)*100/10,0)*10+IF(MOD(ROUND(G14*(1+0.2),2)*100,10)>4,9,-1))/100 -> 3.59 | J14: =ROUND(SUMIFS(repasse_ac!$P:$P,repasse_ac!$A:$A,$A14,repasse_ac!$F:$F,$D14,repasse_ac!$I:$I,"TTC PRÉ"),2) -> 2.91 | K14: =ROUND(SUMIFS(repasse_ac!$P:$P,repasse_ac!$A:$A,$A14,repasse_ac!$F:$F,$D14,repasse_ac!$I:$I,"TTC PÓS"),2) -> 2.83 | L14: =K14-J14 -> -0.08 | M14: =(ROUNDDOWN(ROUND(K14*(1+0.2),2)*100/10,0)*10+IF(MOD(ROUND(K14*(1+0.2),2)*100,10)>4,9,-1))/100 -> 3.39 | N14: =ROUND(SUMIFS(repasse_ac!$J:$J,repasse_ac!$A:$A,$A14,repasse_ac!$F:$F,$D14,repasse_ac!$I:$I,"TTC PRÉ"),2) -> 3.49 | O14: =ROUND(SUMIFS(repasse_ac!$J:$J,repasse_ac!$A:$A,$A14,repasse_ac!$F:$F,$D14,repasse_ac!$I:$I,"TTC PÓS"),2) -> 3.39 | P14: =O14-N14 -> -0.1 | Q14: =ROUND(SUMIFS(repasse_ac!$N:$N,repasse_ac!$A:$A,$A14,repasse_ac!$F:$F,$D14,repasse_ac!$I:$I,"TTC PRÉ"),2) -> 3.29 | R14: =ROUND(SUMIFS(repasse_ac!$N:$N,repasse_ac!$A:$A,$A14,repasse_ac!$F:$F,$D14,repasse_ac!$I:$I,"TTC PÓS"),2) -> 3.29 | S14: =R14-Q14 -> 0
A15: AM | B15: GEO CO | C15: LATA 350 | D15: SLA LT350 | E15: =_xlfn.XLOOKUP($D15,depara_repasse!E:E,depara_repasse!K:K) -> 12 | F15: =ROUND(SUMIFS(repasse_ac!$R:$R,repasse_ac!$A:$A,$A15,repasse_ac!$F:$F,$D15,repasse_ac!$I:$I,"TTC PRÉ"),2) -> 2.96 | G15: =ROUND(SUMIFS(repasse_ac!$R:$R,repasse_ac!$A:$A,$A15,repasse_ac!$F:$F,$D15,repasse_ac!$I:$I,"TTC PÓS"),2) -> 2.96 | H15: =G15-F15 -> 0 | I15: =(ROUNDDOWN(ROUND(G15*(1+0.2),2)*100/10,0)*10+IF(MOD(ROUND(G15*(1+0.2),2)*100,10)>4,9,-1))/100 -> 3.59 | J15: =ROUND(SUMIFS(repasse_ac!$P:$P,repasse_ac!$A:$A,$A15,repasse_ac!$F:$F,$D15,repasse_ac!$I:$I,"TTC PRÉ"),2) -> 2.91 | K15: =ROUND(SUMIFS(repasse_ac!$P:$P,repasse_ac!$A:$A,$A15,repasse_ac!$F:$F,$D15,repasse_ac!$I:$I,"TTC PÓS"),2) -> 2.83 | L15: =K15-J15 -> -0.08 | M15: =(ROUNDDOWN(ROUND(K15*(1+0.2),2)*100/10,0)*10+IF(MOD(ROUND(K15*(1+0.2),2)*100,10)>4,9,-1))/100 -> 3.39 | N15: =ROUND(SUMIFS(repasse_ac!$J:$J,repasse_ac!$A:$A,$A15,repasse_ac!$F:$F,$D15,repasse_ac!$I:$I,"TTC PRÉ"),2) -> 3.49 | O15: =ROUND(SUMIFS(repasse_ac!$J:$J,repasse_ac!$A:$A,$A15,repasse_ac!$F:$F,$D15,repasse_ac!$I:$I,"TTC PÓS"),2) -> 3.39 | P15: =O15-N15 -> -0.1 | Q15: =ROUND(SUMIFS(repasse_ac!$N:$N,repasse_ac!$A:$A,$A15,repasse_ac!$F:$F,$D15,repasse_ac!$I:$I,"TTC PRÉ"),2) -> 3.29 | R15: =ROUND(SUMIFS(repasse_ac!$N:$N,repasse_ac!$A:$A,$A15,repasse_ac!$F:$F,$D15,repasse_ac!$I:$I,"TTC PÓS"),2) -> 3.29 | S15: =R15-Q15 -> 0
A16: AM | B16: GEO CO | C16: LATA 350 | D16: SAB LT350 | E16: =_xlfn.XLOOKUP($D16,depara_repasse!E:E,depara_repasse!K:K) -> 12 | F16: =ROUND(SUMIFS(repasse_ac!$R:$R,repasse_ac!$A:$A,$A16,repasse_ac!$F:$F,$D16,repasse_ac!$I:$I,"TTC PRÉ"),2) -> 2.96 | G16: =ROUND(SUMIFS(repasse_ac!$R:$R,repasse_ac!$A:$A,$A16,repasse_ac!$F:$F,$D16,repasse_ac!$I:$I,"TTC PÓS"),2) -> 2.96 | H16: =G16-F16 -> 0 | I16: =(ROUNDDOWN(ROUND(G16*(1+0.2),2)*100/10,0)*10+IF(MOD(ROUND(G16*(1+0.2),2)*100,10)>4,9,-1))/100 -> 3.59 | J16: =ROUND(SUMIFS(repasse_ac!$P:$P,repasse_ac!$A:$A,$A16,repasse_ac!$F:$F,$D16,repasse_ac!$I:$I,"TTC PRÉ"),2) -> 2.91 | K16: =ROUND(SUMIFS(repasse_ac!$P:$P,repasse_ac!$A:$A,$A16,repasse_ac!$F:$F,$D16,repasse_ac!$I:$I,"TTC PÓS"),2) -> 2.83 | L16: =K16-J16 -> -0.08 | M16: =(ROUNDDOWN(ROUND(K16*(1+0.2),2)*100/10,0)*10+IF(MOD(ROUND(K16*(1+0.2),2)*100,10)>4,9,-1))/100 -> 3.39 | N16: =ROUND(SUMIFS(repasse_ac!$J:$J,repasse_ac!$A:$A,$A16,repasse_ac!$F:$F,$D16,repasse_ac!$I:$I,"TTC PRÉ"),2) -> 3.49 | O16: =ROUND(SUMIFS(repasse_ac!$J:$J,repasse_ac!$A:$A,$A16,repasse_ac!$F:$F,$D16,repasse_ac!$I:$I,"TTC PÓS"),2) -> 3.39 | P16: =O16-N16 -> -0.1 | Q16: =ROUND(SUMIFS(repasse_ac!$N:$N,repasse_ac!$A:$A,$A16,repasse_ac!$F:$F,$D16,repasse_ac!$I:$I,"TTC PRÉ"),2) -> 3.29 | R16: =ROUND(SUMIFS(repasse_ac!$N:$N,repasse_ac!$A:$A,$A16,repasse_ac!$F:$F,$D16,repasse_ac!$I:$I,"TTC PÓS"),2) -> 3.29 | S16: =R16-Q16 -> 0
A17: AM | B17: GEO CO | C17: LATA 350 | D17: TA LT350 | E17: =_xlfn.XLOOKUP($D17,depara_repasse!E:E,depara_repasse!K:K) -> 12 | F17: =ROUND(SUMIFS(repasse_ac!$R:$R,repasse_ac!$A:$A,$A17,repasse_ac!$F:$F,$D17,repasse_ac!$I:$I,"TTC PRÉ"),2) -> 3.33 | G17: =ROUND(SUMIFS(repasse_ac!$R:$R,repasse_ac!$A:$A,$A17,repasse_ac!$F:$F,$D17,repasse_ac!$I:$I,"TTC PÓS"),2) -> 3.33 | H17: =G17-F17 -> 0 | I17: =(ROUNDDOWN(ROUND(G17*(1+0.2),2)*100/10,0)*10+IF(MOD(ROUND(G17*(1+0.2),2)*100,10)>4,9,-1))/100 -> 3.99 | J17: =ROUND(SUMIFS(repasse_ac!$P:$P,repasse_ac!$A:$A,$A17,repasse_ac!$F:$F,$D17,repasse_ac!$I:$I,"TTC PRÉ"),2) -> 2.92 | K17: =ROUND(SUMIFS(repasse_ac!$P:$P,repasse_ac!$A:$A,$A17,repasse_ac!$F:$F,$D17,repasse_ac!$I:$I,"TTC PÓS"),2) -> 2.92 | L17: =K17-J17 -> 0 | M17: =(ROUNDDOWN(ROUND(K17*(1+0.2),2)*100/10,0)*10+IF(MOD(ROUND(K17*(1+0.2),2)*100,10)>4,9,-1))/100 -> 3.49 | N17: =ROUND(SUMIFS(repasse_ac!$J:$J,repasse_ac!$A:$A,$A17,repasse_ac!$F:$F,$D17,repasse_ac!$I:$I,"TTC PRÉ"),2) -> 3.49 | O17: =ROUND(SUMIFS(repasse_ac!$J:$J,repasse_ac!$A:$A,$A17,repasse_ac!$F:$F,$D17,repasse_ac!$I:$I,"TTC PÓS"),2) -> 3.49 | P17: =O17-N17 -> 0 | Q17: =ROUND(SUMIFS(repasse_ac!$N:$N,repasse_ac!$A:$A,$A17,repasse_ac!$F:$F,$D17,repasse_ac!$I:$I,"TTC PRÉ"),2) -> 3.49 | R17: =ROUND(SUMIFS(repasse_ac!$N:$N,repasse_ac!$A:$A,$A17,repasse_ac!$F:$F,$D17,repasse_ac!$I:$I,"TTC PÓS"),2) -> 3.49 | S17: =R17-Q17 -> 0
A18: AM | B18: GEO CO | C18: LATA 350 | D18: PACK 18 | E18: =_xlfn.XLOOKUP($D18,depara_repasse!E:E,depara_repasse!K:K) -> 18 | F18: =ROUND(SUMIFS(repasse_ac!$R:$R,repasse_ac!$A:$A,$A18,repasse_ac!$F:$F,$D18,repasse_ac!$I:$I,"TTC PRÉ"),2) -> 0 | G18: =ROUND(SUMIFS(repasse_ac!$R:$R,repasse_ac!$A:$A,$A18,repasse_ac!$F:$F,$D18,repasse_ac!$I:$I,"TTC PÓS"),2) -> 0 | H18: =G18-F18 -> 0 | I18: =(ROUNDDOWN(ROUND(G18*(1+0.2),2)*100/10,0)*10+IF(MOD(ROUND(G18*(1+0.2),2)*100,10)>4,9,-1))/100 -> -0.01 | J18: =ROUND(SUMIFS(repasse_ac!$P:$P,repasse_ac!$A:$A,$A18,repasse_ac!$F:$F,$D18,repasse_ac!$I:$I,"TTC PRÉ"),2) -> 0 | K18: =ROUND(SUMIFS(repasse_ac!$P:$P,repasse_ac!$A:$A,$A18,repasse_ac!$F:$F,$D18,repasse_ac!$I:$I,"TTC PÓS"),2) -> 0 | L18: =K18-J18 -> 0 | M18: =(ROUNDDOWN(ROUND(K18*(1+0.2),2)*100/10,0)*10+IF(MOD(ROUND(K18*(1+0.2),2)*100,10)>4,9,-1))/100 -> -0.01 | N18: =ROUND(SUMIFS(repasse_ac!$J:$J,repasse_ac!$A:$A,$A18,repasse_ac!$F:$F,$D18,repasse_ac!$I:$I,"TTC PRÉ"),2) -> 0 | O18: =ROUND(SUMIFS(repasse_ac!$J:$J,repasse_ac!$A:$A,$A18,repasse_ac!$F:$F,$D18,repasse_ac!$I:$I,"TTC PÓS"),2) -> 0 | P18: =O18-N18 -> 0 | Q18: =ROUND(SUMIFS(repasse_ac!$N:$N,repasse_ac!$A:$A,$A18,repasse_ac!$F:$F,$D18,repasse_ac!$I:$I,"TTC PRÉ"),2) -> 0 | R18: =ROUND(SUMIFS(repasse_ac!$N:$N,repasse_ac!$A:$A,$A18,repasse_ac!$F:$F,$D18,repasse_ac!$I:$I,"TTC PÓS"),2) -> 0 | S18: =R18-Q18 -> 0
A19: AM | B19: GEO CO | C19: PET 500 | D19: H2OH P500 | E19: =_xlfn.XLOOKUP($D19,depara_repasse!E:E,depara_repasse!K:K) -> 12 | F19: =ROUND(SUMIFS(repasse_ac!$R:$R,repasse_ac!$A:$A,$A19,repasse_ac!$F:$F,$D19,repasse_ac!$I:$I,"TTC PRÉ"),2) -> 4.31 | G19: =ROUND(SUMIFS(repasse_ac!$R:$R,repasse_ac!$A:$A,$A19,repasse_ac!$F:$F,$D19,repasse_ac!$I:$I,"TTC PÓS"),2) -> 4.31 | H19: =G19-F19 -> 0 | I19: =(ROUNDDOWN(ROUND(G19*(1+0.2),2)*100/10,0)*10+IF(MOD(ROUND(G19*(1+0.2),2)*100,10)>4,9,-1))/100 -> 5.19 | J19: =ROUND(SUMIFS(repasse_ac!$P:$P,repasse_ac!$A:$A,$A19,repasse_ac!$F:$F,$D19,repasse_ac!$I:$I,"TTC PRÉ"),2) -> 4.16 | K19: =ROUND(SUMIFS(repasse_ac!$P:$P,repasse_ac!$A:$A,$A19,repasse_ac!$F:$F,$D19,repasse_ac!$I:$I,"TTC PÓS"),2) -> 4.16 | L19: =K19-J19 -> 0 | M19: =(ROUNDDOWN(ROUND(K19*(1+0.2),2)*100/10,0)*10+IF(MOD(ROUND(K19*(1+0.2),2)*100,10)>4,9,-1))/100 -> 4.99 | N19: =ROUND(SUMIFS(repasse_ac!$J:$J,repasse_ac!$A:$A,$A19,repasse_ac!$F:$F,$D19,repasse_ac!$I:$I,"TTC PRÉ"),2) -> 4.99 | O19: =ROUND(SUMIFS(repasse_ac!$J:$J,repasse_ac!$A:$A,$A19,repasse_ac!$F:$F,$D19,repasse_ac!$I:$I,"TTC PÓS"),2) -> 4.99 | P19: =O19-N19 -> 0 | Q19: =ROUND(SUMIFS(repasse_ac!$N:$N,repasse_ac!$A:$A,$A19,repasse_ac!$F:$F,$D19,repasse_ac!$I:$I,"TTC PRÉ"),2) -> 4.79 | R19: =ROUND(SUMIFS(repasse_ac!$N:$N,repasse_ac!$A:$A,$A19,repasse_ac!$F:$F,$D19,repasse_ac!$I:$I,"TTC PÓS"),2) -> 4.79 | S19: =R19-Q19 -> 0
A20: AM | B20: GEO CO | C20: PET 600 | D20: GCA P600 | E20: =_xlfn.XLOOKUP($D20,depara_repasse!E:E,depara_repasse!K:K) -> 12 | F20: =ROUND(SUMIFS(repasse_ac!$R:$R,repasse_ac!$A:$A,$A20,repasse_ac!$F:$F,$D20,repasse_ac!$I:$I,"TTC PRÉ"),2) -> 4.06 | G20: =ROUND(SUMIFS(repasse_ac!$R:$R,repasse_ac!$A:$A,$A20,repasse_ac!$F:$F,$D20,repasse_ac!$I:$I,"TTC PÓS"),2) -> 4.06 | H20: =G20-F20 -> 0 | I20: =(ROUNDDOWN(ROUND(G20*(1+0.2),2)*100/10,0)*10+IF(MOD(ROUND(G20*(1+0.2),2)*100,10)>4,9,-1))/100 -> 4.89 | J20: =ROUND(SUMIFS(repasse_ac!$P:$P,repasse_ac!$A:$A,$A20,repasse_ac!$F:$F,$D20,repasse_ac!$I:$I,"TTC PRÉ"),2) -> 3.75 | K20: =ROUND(SUMIFS(repasse_ac!$P:$P,repasse_ac!$A:$A,$A20,repasse_ac!$F:$F,$D20,repasse_ac!$I:$I,"TTC PÓS"),2) -> 4.17 | L20: =K20-J20 -> 0.42 | M20: =(ROUNDDOWN(ROUND(K20*(1+0.2),2)*100/10,0)*10+IF(MOD(ROUND(K20*(1+0.2),2)*100,10)>4,9,-1))/100 -> 4.99 | N20: =ROUND(SUMIFS(repasse_ac!$J:$J,repasse_ac!$A:$A,$A20,repasse_ac!$F:$F,$D20,repasse_ac!$I:$I,"TTC PRÉ"),2) -> 4.49 | O20: =ROUND(SUMIFS(repasse_ac!$J:$J,repasse_ac!$A:$A,$A20,repasse_ac!$F:$F,$D20,repasse_ac!$I:$I,"TTC PÓS"),2) -> 4.99 | P20: =O20-N20 -> 0.5 | Q20: =ROUND(SUMIFS(repasse_ac!$N:$N,repasse_ac!$A:$A,$A20,repasse_ac!$F:$F,$D20,repasse_ac!$I:$I,"TTC PRÉ"),2) -> 4.49 | R20: =ROUND(SUMIFS(repasse_ac!$N:$N,repasse_ac!$A:$A,$A20,repasse_ac!$F:$F,$D20,repasse_ac!$I:$I,"TTC PÓS"),2) -> 4.49 | S20: =R20-Q20 -> 0
A21: AM | B21: GEO CO | C21: PET 600 | D21: GCAD P600 | E21: =_xlfn.XLOOKUP($D21,depara_repasse!E:E,depara_repasse!K:K) -> 12 | F21: =ROUND(SUMIFS(repasse_ac!$R:$R,repasse_ac!$A:$A,$A21,repasse_ac!$F:$F,$D21,repasse_ac!$I:$I,"TTC PRÉ"),2) -> 4.06 | G21: =ROUND(SUMIFS(repasse_ac!$R:$R,repasse_ac!$A:$A,$A21,repasse_ac!$F:$F,$D21,repasse_ac!$I:$I,"TTC PÓS"),2) -> 4.06 | H21: =G21-F21 -> 0 | I21: =(ROUNDDOWN(ROUND(G21*(1+0.2),2)*100/10,0)*10+IF(MOD(ROUND(G21*(1+0.2),2)*100,10)>4,9,-1))/100 -> 4.89 | J21: =ROUND(SUMIFS(repasse_ac!$P:$P,repasse_ac!$A:$A,$A21,repasse_ac!$F:$F,$D21,repasse_ac!$I:$I,"TTC PRÉ"),2) -> 3.75 | K21: =ROUND(SUMIFS(repasse_ac!$P:$P,repasse_ac!$A:$A,$A21,repasse_ac!$F:$F,$D21,repasse_ac!$I:$I,"TTC PÓS"),2) -> 4.17 | L21: =K21-J21 -> 0.42 | M21: =(ROUNDDOWN(ROUND(K21*(1+0.2),2)*100/10,0)*10+IF(MOD(ROUND(K21*(1+0.2),2)*100,10)>4,9,-1))/100 -> 4.99 | N21: =ROUND(SUMIFS(repasse_ac!$J:$J,repasse_ac!$A:$A,$A21,repasse_ac!$F:$F,$D21,repasse_ac!$I:$I,"TTC PRÉ"),2) -> 4.49 | O21: =ROUND(SUMIFS(repasse_ac!$J:$J,repasse_ac!$A:$A,$A21,repasse_ac!$F:$F,$D21,repasse_ac!$I:$I,"TTC PÓS"),2) -> 4.99 | P21: =O21-N21 -> 0.5 | Q21: =ROUND(SUMIFS(repasse_ac!$N:$N,repasse_ac!$A:$A,$A21,repasse_ac!$F:$F,$D21,repasse_ac!$I:$I,"TTC PRÉ"),2) -> 4.49 | R21: =ROUND(SUMIFS(repasse_ac!$N:$N,repasse_ac!$A:$A,$A21,repasse_ac!$F:$F,$D21,repasse_ac!$I:$I,"TTC PÓS"),2) -> 4.49 | S21: =R21-Q21 -> 0
A22: AM | B22: GEO CO | C22: PET 600 | D22: PC P600 | E22: =_xlfn.XLOOKUP($D22,depara_repasse!E:E,depara_repasse!K:K) -> 12 | F22: =ROUND(SUMIFS(repasse_ac!$R:$R,repasse_ac!$A:$A,$A22,repasse_ac!$F:$F,$D22,repasse_ac!$I:$I,"TTC PRÉ"),2) -> 3.87 | G22: =ROUND(SUMIFS(repasse_ac!$R:$R,repasse_ac!$A:$A,$A22,repasse_ac!$F:$F,$D22,repasse_ac!$I:$I,"TTC PÓS"),2) -> 3.87 | H22: =G22-F22 -> 0 | I22: =(ROUNDDOWN(ROUND(G22*(1+0.2),2)*100/10,0)*10+IF(MOD(ROUND(G22*(1+0.2),2)*100,10)>4,9,-1))/100 -> 4.59 | J22: =ROUND(SUMIFS(repasse_ac!$P:$P,repasse_ac!$A:$A,$A22,repasse_ac!$F:$F,$D22,repasse_ac!$I:$I,"TTC PRÉ"),2) -> 3.51 | K22: =ROUND(SUMIFS(repasse_ac!$P:$P,repasse_ac!$A:$A,$A22,repasse_ac!$F:$F,$D22,repasse_ac!$I:$I,"TTC PÓS"),2) -> 3.76 | L22: =K22-J22 -> 0.25 | M22: =(ROUNDDOWN(ROUND(K22*(1+0.2),2)*100/10,0)*10+IF(MOD(ROUND(K22*(1+0.2),2)*100,10)>4,9,-1))/100 -> 4.49 | N22: =ROUND(SUMIFS(repasse_ac!$J:$J,repasse_ac!$A:$A,$A22,repasse_ac!$F:$F,$D22,repasse_ac!$I:$I,"TTC PRÉ"),2) -> 4.19 | O22: =ROUND(SUMIFS(repasse_ac!$J:$J,repasse_ac!$A:$A,$A22,repasse_ac!$F:$F,$D22,repasse_ac!$I:$I,"TTC PÓS"),2) -> 4.49 | P22: =O22-N22 -> 0.3 | Q22: =ROUND(SUMIFS(repasse_ac!$N:$N,repasse_ac!$A:$A,$A22,repasse_ac!$F:$F,$D22,repasse_ac!$I:$I,"TTC PRÉ"),2) -> 4.29 | R22: =ROUND(SUMIFS(repasse_ac!$N:$N,repasse_ac!$A:$A,$A22,repasse_ac!$F:$F,$D22,repasse_ac!$I:$I,"TTC PÓS"),2) -> 4.29 | S22: =R22-Q22 -> 0
... A51: AM | B51: GEO CO | C51: PET 1L | D51: FUSION P1 | E51: =_xlfn.XLOOKUP($D51,depara_repasse!E:E,depara_repasse!K:K) -> 6 | F51: =ROUND(SUMIFS(repasse_ac!$R:$R,repasse_ac!$A:$A,$A51,repasse_ac!$F:$F,$D51,repasse_ac!$I:$I,"TTC PRÉ"),2) -> 6.75 | G51: =ROUND(SUMIFS(repasse_ac!$R:$R,repasse_ac!$A:$A,$A51,repasse_ac!$F:$F,$D51,repasse_ac!$I:$I,"TTC PÓS"),2) -> 6.75 | H51: =G51-F51 -> 0 | I51: =(ROUNDDOWN(ROUND(G51*(1+0.2),2)*100/10,0)*10+IF(MOD(ROUND(G51*(1+0.2),2)*100,10)>4,9,-1))/100 -> 8.09 | J51: =ROUND(SUMIFS(repasse_ac!$P:$P,repasse_ac!$A:$A,$A51,repasse_ac!$F:$F,$D51,repasse_ac!$I:$I,"TTC PRÉ"),2) -> 6.08 | K51: =ROUND(SUMIFS(repasse_ac!$P:$P,repasse_ac!$A:$A,$A51,repasse_ac!$F:$F,$D51,repasse_ac!$I:$I,"TTC PÓS"),2) -> 6.08 | L51: =K51-J51 -> 0 | M51: =(ROUNDDOWN(ROUND(K51*(1+0.2),2)*100/10,0)*10+IF(MOD(ROUND(K51*(1+0.2),2)*100,10)>4,9,-1))/100 -> 7.29 | N51: =ROUND(SUMIFS(repasse_ac!$J:$J,repasse_ac!$A:$A,$A51,repasse_ac!$F:$F,$D51,repasse_ac!$I:$I,"TTC PRÉ"),2) -> 8.49 | O51: =ROUND(SUMIFS(repasse_ac!$J:$J,repasse_ac!$A:$A,$A51,repasse_ac!$F:$F,$D51,repasse_ac!$I:$I,"TTC PÓS"),2) -> 8.49 | P51: =O51-N51 -> 0 | Q51: =ROUND(SUMIFS(repasse_ac!$N:$N,repasse_ac!$A:$A,$A51,repasse_ac!$F:$F,$D51,repasse_ac!$I:$I,"TTC PRÉ"),2) -> 7.49 | R51: =ROUND(SUMIFS(repasse_ac!$N:$N,repasse_ac!$A:$A,$A51,repasse_ac!$F:$F,$D51,repasse_ac!$I:$I,"TTC PÓS"),2) -> 7.49 | S51: =R51-Q51 -> 0
A52: AM | B52: GEO CO | C52: PET 2L | D52: FUSION P2 | E52: =_xlfn.XLOOKUP($D52,depara_repasse!E:E,depara_repasse!K:K) -> 6 | F52: =ROUND(SUMIFS(repasse_ac!$R:$R,repasse_ac!$A:$A,$A52,repasse_ac!$F:$F,$D52,repasse_ac!$I:$I,"TTC PRÉ"),2) -> 9 | G52: =ROUND(SUMIFS(repasse_ac!$R:$R,repasse_ac!$A:$A,$A52,repasse_ac!$F:$F,$D52,repasse_ac!$I:$I,"TTC PÓS"),2) -> 9 | H52: =G52-F52 -> 0 | I52: 10.49 | J52: =ROUND(SUMIFS(repasse_ac!$P:$P,repasse_ac!$A:$A,$A52,repasse_ac!$F:$F,$D52,repasse_ac!$I:$I,"TTC PRÉ"),2) -> 7.5 | K52: =ROUND(SUMIFS(repasse_ac!$P:$P,repasse_ac!$A:$A,$A52,repasse_ac!$F:$F,$D52,repasse_ac!$I:$I,"TTC PÓS"),2) -> 7.5 | L52: =K52-J52 -> 0 | M52: 9.99 | N52: =ROUND(SUMIFS(repasse_ac!$J:$J,repasse_ac!$A:$A,$A52,repasse_ac!$F:$F,$D52,repasse_ac!$I:$I,"TTC PRÉ"),2) -> 10.49 | O52: =ROUND(SUMIFS(repasse_ac!$J:$J,repasse_ac!$A:$A,$A52,repasse_ac!$F:$F,$D52,repasse_ac!$I:$I,"TTC PÓS"),2) -> 10.49 | P52: =O52-N52 -> 0 | Q52: =ROUND(SUMIFS(repasse_ac!$N:$N,repasse_ac!$A:$A,$A52,repasse_ac!$F:$F,$D52,repasse_ac!$I:$I,"TTC PRÉ"),2) -> 9.99 | R52: =ROUND(SUMIFS(repasse_ac!$N:$N,repasse_ac!$A:$A,$A52,repasse_ac!$F:$F,$D52,repasse_ac!$I:$I,"TTC PÓS"),2) -> 9.99 | S52: =R52-Q52 -> 0
A53: AM | B53: GEO CO | C53: LATA 250 | D53: RB 250 | E53: =_xlfn.XLOOKUP($D53,depara_repasse!E:E,depara_repasse!K:K) -> 4 | F53: =ROUND(SUMIFS(repasse_ac!$R:$R,repasse_ac!$A:$A,$A53,repasse_ac!$F:$F,$D53,repasse_ac!$I:$I,"TTC PRÉ"),2) -> 8.05 | G53: =ROUND(SUMIFS(repasse_ac!$R:$R,repasse_ac!$A:$A,$A53,repasse_ac!$F:$F,$D53,repasse_ac!$I:$I,"TTC PÓS"),2) -> 8.05 | H53: =G53-F53 -> 0 | I53: =(ROUNDDOWN(ROUND(G53*(1+0.2),2)*100/10,0)*10+IF(MOD(ROUND(G53*(1+0.2),2)*100,10)>4,9,-1))/100 -> 9.69 | J53: =ROUND(SUMIFS(repasse_ac!$P:$P,repasse_ac!$A:$A,$A53,repasse_ac!$F:$F,$D53,repasse_ac!$I:$I,"TTC PRÉ"),2) -> 7.98 | K53: =ROUND(SUMIFS(repasse_ac!$P:$P,repasse_ac!$A:$A,$A53,repasse_ac!$F:$F,$D53,repasse_ac!$I:$I,"TTC PÓS"),2) -> 7.98 | L53: =K53-J53 -> 0 | M53: =(ROUNDDOWN(ROUND(K53*(1+0.2),2)*100/10,0)*10+IF(MOD(ROUND(K53*(1+0.2),2)*100,10)>4,9,-1))/100 -> 9.59 | N53: =ROUND(SUMIFS(repasse_ac!$J:$J,repasse_ac!$A:$A,$A53,repasse_ac!$F:$F,$D53,repasse_ac!$I:$I,"TTC PRÉ"),2) -> 10.49 | O53: =ROUND(SUMIFS(repasse_ac!$J:$J,repasse_ac!$A:$A,$A53,repasse_ac!$F:$F,$D53,repasse_ac!$I:$I,"TTC PÓS"),2) -> 10.49 | P53: =O53-N53 -> 0 | Q53: =ROUND(SUMIFS(repasse_ac!$N:$N,repasse_ac!$A:$A,$A53,repasse_ac!$F:$F,$D53,repasse_ac!$I:$I,"TTC PRÉ"),2) -> 10.49 | R53: =ROUND(SUMIFS(repasse_ac!$N:$N,repasse_ac!$A:$A,$A53,repasse_ac!$F:$F,$D53,repasse_ac!$I:$I,"TTC PÓS"),2) -> 10.49 | S53: =R53-Q53 -> 0
A54: AM | B54: GEO CO | C54: LATA 355 | D54: RB 355 | E54: =_xlfn.XLOOKUP($D54,depara_repasse!E:E,depara_repasse!K:K) -> 4 | F54: =ROUND(SUMIFS(repasse_ac!$R:$R,repasse_ac!$A:$A,$A54,repasse_ac!$F:$F,$D54,repasse_ac!$I:$I,"TTC PRÉ"),2) -> 10.25 | G54: =ROUND(SUMIFS(repasse_ac!$R:$R,repasse_ac!$A:$A,$A54,repasse_ac!$F:$F,$D54,repasse_ac!$I:$I,"TTC PÓS"),2) -> 10.25 | H54: =G54-F54 -> 0 | I54: =(ROUNDDOWN(ROUND(G54*(1+0.2),2)*100/10,0)*10+IF(MOD(ROUND(G54*(1+0.2),2)*100,10)>4,9,-1))/100 -> 12.29 | J54: =ROUND(SUMIFS(repasse_ac!$P:$P,repasse_ac!$A:$A,$A54,repasse_ac!$F:$F,$D54,repasse_ac!$I:$I,"TTC PRÉ"),2) -> 9.53 | K54: =ROUND(SUMIFS(repasse_ac!$P:$P,repasse_ac!$A:$A,$A54,repasse_ac!$F:$F,$D54,repasse_ac!$I:$I,"TTC PÓS"),2) -> 9.53 | L54: =K54-J54 -> 0 | M54: =(ROUNDDOWN(ROUND(K54*(1+0.2),2)*100/10,0)*10+IF(MOD(ROUND(K54*(1+0.2),2)*100,10)>4,9,-1))/100 -> 11.39 | N54: =ROUND(SUMIFS(repasse_ac!$J:$J,repasse_ac!$A:$A,$A54,repasse_ac!$F:$F,$D54,repasse_ac!$I:$I,"TTC PRÉ"),2) -> 13.99 | O54: =ROUND(SUMIFS(repasse_ac!$J:$J,repasse_ac!$A:$A,$A54,repasse_ac!$F:$F,$D54,repasse_ac!$I:$I,"TTC PÓS"),2) -> 13.99 | P54: =O54-N54 -> 0 | Q54: =ROUND(SUMIFS(repasse_ac!$N:$N,repasse_ac!$A:$A,$A54,repasse_ac!$F:$F,$D54,repasse_ac!$I:$I,"TTC PRÉ"),2) -> 13.99 | R54: =ROUND(SUMIFS(repasse_ac!$N:$N,repasse_ac!$A:$A,$A54,repasse_ac!$F:$F,$D54,repasse_ac!$I:$I,"TTC PÓS"),2) -> 13.99 | S54: =R54-Q54 -> 0
A55: AM | B55: GEO CO | C55: PET 200 | D55: PCB P200 | E55: 12 | F55: =ROUND(SUMIFS(repasse_ac!$R:$R,repasse_ac!$A:$A,$A55,repasse_ac!$F:$F,$D55,repasse_ac!$I:$I,"TTC PRÉ"),2) -> 1.62 | G55: =ROUND(SUMIFS(repasse_ac!$R:$R,repasse_ac!$A:$A,$A55,repasse_ac!$F:$F,$D55,repasse_ac!$I:$I,"TTC PÓS"),2) -> 1.71 | H55: =G55-F55 -> 0.09 | I55: =(ROUNDDOWN(ROUND(G55*(1+0.2),2)*100/10,0)*10+IF(MOD(ROUND(G55*(1+0.2),2)*100,10)>4,9,-1))/100 -> 2.09 | J55: =ROUND(SUMIFS(repasse_ac!$P:$P,repasse_ac!$A:$A,$A55,repasse_ac!$F:$F,$D55,repasse_ac!$I:$I,"TTC PRÉ"),2) -> 1.59 | K55: =ROUND(SUMIFS(repasse_ac!$P:$P,repasse_ac!$A:$A,$A55,repasse_ac!$F:$F,$D55,repasse_ac!$I:$I,"TTC PÓS"),2) -> 1.67 | L55: =K55-J55 -> 0.08 | M55: =(ROUNDDOWN(ROUND(K55*(1+0.2),2)*100/10,0)*10+IF(MOD(ROUND(K55*(1+0.2),2)*100,10)>4,9,-1))/100 -> 1.99 | N55: =ROUND(SUMIFS(repasse_ac!$J:$J,repasse_ac!$A:$A,$A55,repasse_ac!$F:$F,$D55,repasse_ac!$I:$I,"TTC PRÉ"),2) -> 1.89 | O55: =ROUND(SUMIFS(repasse_ac!$J:$J,repasse_ac!$A:$A,$A55,repasse_ac!$F:$F,$D55,repasse_ac!$I:$I,"TTC PÓS"),2) -> 1.99 | P55: =O55-N55 -> 0.1 | Q55: =ROUND(SUMIFS(repasse_ac!$N:$N,repasse_ac!$A:$A,$A55,repasse_ac!$F:$F,$D55,repasse_ac!$I:$I,"TTC PRÉ"),2) -> 1.79 | R55: =ROUND(SUMIFS(repasse_ac!$N:$N,repasse_ac!$A:$A,$A55,repasse_ac!$F:$F,$D55,repasse_ac!$I:$I,"TTC PÓS"),2) -> 1.89 | S55: =R55-Q55 -> 0.1
A56: AM | B56: GEO CO | C56: LATA 350 | D56: PCB LT350 | E56: 12 | F56: =ROUND(SUMIFS(repasse_ac!$R:$R,repasse_ac!$A:$A,$A56,repasse_ac!$F:$F,$D56,repasse_ac!$I:$I,"TTC PRÉ"),2) -> 2.96 | G56: =ROUND(SUMIFS(repasse_ac!$R:$R,repasse_ac!$A:$A,$A56,repasse_ac!$F:$F,$D56,repasse_ac!$I:$I,"TTC PÓS"),2) -> 2.96 | H56: =G56-F56 -> 0 | I56: =(ROUNDDOWN(ROUND(G56*(1+0.2),2)*100/10,0)*10+IF(MOD(ROUND(G56*(1+0.2),2)*100,10)>4,9,-1))/100 -> 3.59 | J56: =ROUND(SUMIFS(repasse_ac!$P:$P,repasse_ac!$A:$A,$A56,repasse_ac!$F:$F,$D56,repasse_ac!$I:$I,"TTC PRÉ"),2) -> 2.91 | K56: =ROUND(SUMIFS(repasse_ac!$P:$P,repasse_ac!$A:$A,$A56,repasse_ac!$F:$F,$D56,repasse_ac!$I:$I,"TTC PÓS"),2) -> 2.83 | L56: =K56-J56 -> -0.08 | M56: =(ROUNDDOWN(ROUND(K56*(1+0.2),2)*100/10,0)*10+IF(MOD(ROUND(K56*(1+0.2),2)*100,10)>4,9,-1))/100 -> 3.39 | N56: =ROUND(SUMIFS(repasse_ac!$J:$J,repasse_ac!$A:$A,$A56,repasse_ac!$F:$F,$D56,repasse_ac!$I:$I,"TTC PRÉ"),2) -> 3.49 | O56: =ROUND(SUMIFS(repasse_ac!$J:$J,repasse_ac!$A:$A,$A56,repasse_ac!$F:$F,$D56,repasse_ac!$I:$I,"TTC PÓS"),2) -> 3.39 | P56: =O56-N56 -> -0.1 | Q56: =ROUND(SUMIFS(repasse_ac!$N:$N,repasse_ac!$A:$A,$A56,repasse_ac!$F:$F,$D56,repasse_ac!$I:$I,"TTC PRÉ"),2) -> 3.29 | R56: =ROUND(SUMIFS(repasse_ac!$N:$N,repasse_ac!$A:$A,$A56,repasse_ac!$F:$F,$D56,repasse_ac!$I:$I,"TTC PÓS"),2) -> 3.29 | S56: =R56-Q56 -> 0
A57: AM | B57: GEO CO | C57: PET 1L | D57: PCB P1 | E57: 6 | F57: =ROUND(SUMIFS(repasse_ac!$R:$R,repasse_ac!$A:$A,$A57,repasse_ac!$F:$F,$D57,repasse_ac!$I:$I,"TTC PRÉ"),2) -> 4.11 | G57: =ROUND(SUMIFS(repasse_ac!$R:$R,repasse_ac!$A:$A,$A57,repasse_ac!$F:$F,$D57,repasse_ac!$I:$I,"TTC PÓS"),2) -> 4.37 | H57: =G57-F57 -> 0.26 | I57: =(ROUNDDOWN(ROUND(G57*(1+0.2),2)*100/10,0)*10+IF(MOD(ROUND(G57*(1+0.2),2)*100,10)>4,9,-1))/100 -> 5.19 | J57: =ROUND(SUMIFS(repasse_ac!$P:$P,repasse_ac!$A:$A,$A57,repasse_ac!$F:$F,$D57,repasse_ac!$I:$I,"TTC PRÉ"),2) -> 4.01 | K57: =ROUND(SUMIFS(repasse_ac!$P:$P,repasse_ac!$A:$A,$A57,repasse_ac!$F:$F,$D57,repasse_ac!$I:$I,"TTC PÓS"),2) -> 3.33 | L57: =K57-J57 -> -0.68 | M57: =(ROUNDDOWN(ROUND(K57*(1+0.2),2)*100/10,0)*10+IF(MOD(ROUND(K57*(1+0.2),2)*100,10)>4,9,-1))/100 -> 3.99 | N57: =ROUND(SUMIFS(repasse_ac!$J:$J,repasse_ac!$A:$A,$A57,repasse_ac!$F:$F,$D57,repasse_ac!$I:$I,"TTC PRÉ"),2) -> 4.79 | O57: =ROUND(SUMIFS(repasse_ac!$J:$J,repasse_ac!$A:$A,$A57,repasse_ac!$F:$F,$D57,repasse_ac!$I:$I,"TTC PÓS"),2) -> 4.99 | P57: =O57-N57 -> 0.2 | Q57: =ROUND(SUMIFS(repasse_ac!$N:$N,repasse_ac!$A:$A,$A57,repasse_ac!$F:$F,$D57,repasse_ac!$I:$I,"TTC PRÉ"),2) -> 4.69 | R57: =ROUND(SUMIFS(repasse_ac!$N:$N,repasse_ac!$A:$A,$A57,repasse_ac!$F:$F,$D57,repasse_ac!$I:$I,"TTC PÓS"),2) -> 4.99 | S57: =R57-Q57 -> 0.3
A58: AM | B58: GEO CO | C58: PET 1,5L | D58: PCB P1,5 | E58: 6 | F58: =ROUND(SUMIFS(repasse_ac!$R:$R,repasse_ac!$A:$A,$A58,repasse_ac!$F:$F,$D58,repasse_ac!$I:$I,"TTC PRÉ"),2) -> 5.4 | G58: =ROUND(SUMIFS(repasse_ac!$R:$R,repasse_ac!$A:$A,$A58,repasse_ac!$F:$F,$D58,repasse_ac!$I:$I,"TTC PÓS"),2) -> 5.4 | H58: =G58-F58 -> 0 | I58: =(ROUNDDOWN(ROUND(G58*(1+0.2),2)*100/10,0)*10+IF(MOD(ROUND(G58*(1+0.2),2)*100,10)>4,9,-1))/100 -> 6.49 | J58: =ROUND(SUMIFS(repasse_ac!$P:$P,repasse_ac!$A:$A,$A58,repasse_ac!$F:$F,$D58,repasse_ac!$I:$I,"TTC PRÉ"),2) -> 5.26 | K58: =ROUND(SUMIFS(repasse_ac!$P:$P,repasse_ac!$A:$A,$A58,repasse_ac!$F:$F,$D58,repasse_ac!$I:$I,"TTC PÓS"),2) -> 4.99 | L58: =K58-J58 -> -0.27 | M58: =(ROUNDDOWN(ROUND(K58*(1+0.2),2)*100/10,0)*10+IF(MOD(ROUND(K58*(1+0.2),2)*100,10)>4,9,-1))/100 -> 5.99 | N58: =ROUND(SUMIFS(repasse_ac!$J:$J,repasse_ac!$A:$A,$A58,repasse_ac!$F:$F,$D58,repasse_ac!$I:$I,"TTC PRÉ"),2) -> 6.29 | O58: =ROUND(SUMIFS(repasse_ac!$J:$J,repasse_ac!$A:$A,$A58,repasse_ac!$F:$F,$D58,repasse_ac!$I:$I,"TTC PÓS"),2) -> 6.29 | P58: =O58-N58 -> 0 | Q58: =ROUND(SUMIFS(repasse_ac!$N:$N,repasse_ac!$A:$A,$A58,repasse_ac!$F:$F,$D58,repasse_ac!$I:$I,"TTC PRÉ"),2) -> 5.99 | R58: =ROUND(SUMIFS(repasse_ac!$N:$N,repasse_ac!$A:$A,$A58,repasse_ac!$F:$F,$D58,repasse_ac!$I:$I,"TTC PÓS"),2) -> 5.99 | S58: =R58-Q58 -> 0
A59: AM | B59: GEO CO | C59: PET 2L | D59: PCB P2 | E59: 6 | F59: =ROUND(SUMIFS(repasse_ac!$R:$R,repasse_ac!$A:$A,$A59,repasse_ac!$F:$F,$D59,repasse_ac!$I:$I,"TTC PRÉ"),2) -> 8.07 | G59: =ROUND(SUMIFS(repasse_ac!$R:$R,repasse_ac!$A:$A,$A59,repasse_ac!$F:$F,$D59,repasse_ac!$I:$I,"TTC PÓS"),2) -> 7.4 | H59: =G59-F59 -> -0.67 | I59: =(ROUNDDOWN(ROUND(G59*(1+0.2),2)*100/10,0)*10+IF(MOD(ROUND(G59*(1+0.2),2)*100,10)>4,9,-1))/100 -> 8.89 | J59: =ROUND(SUMIFS(repasse_ac!$P:$P,repasse_ac!$A:$A,$A59,repasse_ac!$F:$F,$D59,repasse_ac!$I:$I,"TTC PRÉ"),2) -> 7.34 | K59: =ROUND(SUMIFS(repasse_ac!$P:$P,repasse_ac!$A:$A,$A59,repasse_ac!$F:$F,$D59,repasse_ac!$I:$I,"TTC PÓS"),2) -> 6.67 | L59: =K59-J59 -> -0.67 | M59: =(ROUNDDOWN(ROUND(K59*(1+0.2),2)*100/10,0)*10+IF(MOD(ROUND(K59*(1+0.2),2)*100,10)>4,9,-1))/100 -> 7.99 | N59: =ROUND(SUMIFS(repasse_ac!$J:$J,repasse_ac!$A:$A,$A59,repasse_ac!$F:$F,$D59,repasse_ac!$I:$I,"TTC PRÉ"),2) -> 8.79 | O59: =ROUND(SUMIFS(repasse_ac!$J:$J,repasse_ac!$A:$A,$A59,repasse_ac!$F:$F,$D59,repasse_ac!$I:$I,"TTC PÓS"),2) -> 7.99 | P59: =O59-N59 -> -0.8 | Q59: =ROUND(SUMIFS(repasse_ac!$N:$N,repasse_ac!$A:$A,$A59,repasse_ac!$F:$F,$D59,repasse_ac!$I:$I,"TTC PRÉ"),2) -> 8.49 | R59: =ROUND(SUMIFS(repasse_ac!$N:$N,repasse_ac!$A:$A,$A59,repasse_ac!$F:$F,$D59,repasse_ac!$I:$I,"TTC PÓS"),2) -> 7.79 | S59: =R59-Q59 -> -0.7
A60: RR/AC | B60: GEO CO | C60: PET 200 | D60: GCA P200 | E60: =_xlfn.XLOOKUP($D60,depara_repasse!E:E,depara_repasse!K:K) -> 12 | F60: =ROUND(SUMIFS(repasse_ac!$R:$R,repasse_ac!$A:$A,$A60,repasse_ac!$F:$F,$D60,repasse_ac!$I:$I,"TTC PRÉ"),2) -> 1.72 | G60: =ROUND(SUMIFS(repasse_ac!$R:$R,repasse_ac!$A:$A,$A60,repasse_ac!$F:$F,$D60,repasse_ac!$I:$I,"TTC PÓS"),2) -> 1.72 | H60: =G60-F60 -> 0 | I60: =(ROUNDDOWN(ROUND(G60*(1+0.2),2)*100/10,0)*10+IF(MOD(ROUND(G60*(1+0.2),2)*100,10)>4,9,-1))/100 -> 2.09 | J60: =ROUND(SUMIFS(repasse_ac!$P:$P,repasse_ac!$A:$A,$A60,repasse_ac!$F:$F,$D60,repasse_ac!$I:$I,"TTC PRÉ"),2) -> 1.67 | K60: =ROUND(SUMIFS(repasse_ac!$P:$P,repasse_ac!$A:$A,$A60,repasse_ac!$F:$F,$D60,repasse_ac!$I:$I,"TTC PÓS"),2) -> 1.67 | L60: =K60-J60 -> 0 | M60: =(ROUNDDOWN(ROUND(K60*(1+0.2),2)*100/10,0)*10+IF(MOD(ROUND(K60*(1+0.2),2)*100,10)>4,9,-1))/100 -> 1.99 | N60: =ROUND(SUMIFS(repasse_ac!$J:$J,repasse_ac!$A:$A,$A60,repasse_ac!$F:$F,$D60,repasse_ac!$I:$I,"TTC PRÉ"),2) -> 1.99 | O60: =ROUND(SUMIFS(repasse_ac!$J:$J,repasse_ac!$A:$A,$A60,repasse_ac!$F:$F,$D60,repasse_ac!$I:$I,"TTC PÓS"),2) -> 1.99 | P60: =O60-N60 -> 0 | Q60: =ROUND(SUMIFS(repasse_ac!$N:$N,repasse_ac!$A:$A,$A60,repasse_ac!$F:$F,$D60,repasse_ac!$I:$I,"TTC PRÉ"),2) -> 1.89 | R60: =ROUND(SUMIFS(repasse_ac!$N:$N,repasse_ac!$A:$A,$A60,repasse_ac!$F:$F,$D60,repasse_ac!$I:$I,"TTC PÓS"),2) -> 1.89 | S60: =R60-Q60 -> 0
A61: RR/AC | B61: GEO CO | C61: PET 200 | D61: GCAD P200 | E61: =_xlfn.XLOOKUP($D61,depara_repasse!E:E,depara_repasse!K:K) -> 12 | F61: =ROUND(SUMIFS(repasse_ac!$R:$R,repasse_ac!$A:$A,$A61,repasse_ac!$F:$F,$D61,repasse_ac!$I:$I,"TTC PRÉ"),2) -> 1.72 | G61: =ROUND(SUMIFS(repasse_ac!$R:$R,repasse_ac!$A:$A,$A61,repasse_ac!$F:$F,$D61,repasse_ac!$I:$I,"TTC PÓS"),2) -> 1.72 | H61: =G61-F61 -> 0 | I61: =(ROUNDDOWN(ROUND(G61*(1+0.2),2)*100/10,0)*10+IF(MOD(ROUND(G61*(1+0.2),2)*100,10)>4,9,-1))/100 -> 2.09 | J61: =ROUND(SUMIFS(repasse_ac!$P:$P,repasse_ac!$A:$A,$A61,repasse_ac!$F:$F,$D61,repasse_ac!$I:$I,"TTC PRÉ"),2) -> 1.67 | K61: =ROUND(SUMIFS(repasse_ac!$P:$P,repasse_ac!$A:$A,$A61,repasse_ac!$F:$F,$D61,repasse_ac!$I:$I,"TTC PÓS"),2) -> 1.67 | L61: =K61-J61 -> 0 | M61: =(ROUNDDOWN(ROUND(K61*(1+0.2),2)*100/10,0)*10+IF(MOD(ROUND(K61*(1+0.2),2)*100,10)>4,9,-1))/100 -> 1.99 | N61: =ROUND(SUMIFS(repasse_ac!$J:$J,repasse_ac!$A:$A,$A61,repasse_ac!$F:$F,$D61,repasse_ac!$I:$I,"TTC PRÉ"),2) -> 1.99 | O61: =ROUND(SUMIFS(repasse_ac!$J:$J,repasse_ac!$A:$A,$A61,repasse_ac!$F:$F,$D61,repasse_ac!$I:$I,"TTC PÓS"),2) -> 1.99 | P61: =O61-N61 -> 0 | Q61: =ROUND(SUMIFS(repasse_ac!$N:$N,repasse_ac!$A:$A,$A61,repasse_ac!$F:$F,$D61,repasse_ac!$I:$I,"TTC PRÉ"),2) -> 1.89 | R61: =ROUND(SUMIFS(repasse_ac!$N:$N,repasse_ac!$A:$A,$A61,repasse_ac!$F:$F,$D61,repasse_ac!$I:$I,"TTC PÓS"),2) -> 1.89 | S61: =R61-Q61 -> 0
A62: RR/AC | B62: GEO CO | C62: PET 200 | D62: PC P200 | E62: =_xlfn.XLOOKUP($D62,depara_repasse!E:E,depara_repasse!K:K) -> 12 | F62: =ROUND(SUMIFS(repasse_ac!$R:$R,repasse_ac!$A:$A,$A62,repasse_ac!$F:$F,$D62,repasse_ac!$I:$I,"TTC PRÉ"),2) -> 1.63 | G62: =ROUND(SUMIFS(repasse_ac!$R:$R,repasse_ac!$A:$A,$A62,repasse_ac!$F:$F,$D62,repasse_ac!$I:$I,"TTC PÓS"),2) -> 1.72 | H62: =G62-F62 -> 0.09 | I62: =(ROUNDDOWN(ROUND(G62*(1+0.2),2)*100/10,0)*10+IF(MOD(ROUND(G62*(1+0.2),2)*100,10)>4,9,-1))/100 -> 2.09 | J62: =ROUND(SUMIFS(repasse_ac!$P:$P,repasse_ac!$A:$A,$A62,repasse_ac!$F:$F,$D62,repasse_ac!$I:$I,"TTC PRÉ"),2) -> 1.59 | K62: =ROUND(SUMIFS(repasse_ac!$P:$P,repasse_ac!$A:$A,$A62,repasse_ac!$F:$F,$D62,repasse_ac!$I:$I,"TTC PÓS"),2) -> 1.67 | L62: =K62-J62 -> 0.08 | M62: =(ROUNDDOWN(ROUND(K62*(1+0.2),2)*100/10,0)*10+IF(MOD(ROUND(K62*(1+0.2),2)*100,10)>4,9,-1))/100 -> 1.99 | N62: =ROUND(SUMIFS(repasse_ac!$J:$J,repasse_ac!$A:$A,$A62,repasse_ac!$F:$F,$D62,repasse_ac!$I:$I,"TTC PRÉ"),2) -> 1.89 | O62: =ROUND(SUMIFS(repasse_ac!$J:$J,repasse_ac!$A:$A,$A62,repasse_ac!$F:$F,$D62,repasse_ac!$I:$I,"TTC PÓS"),2) -> 1.99 | P62: =O62-N62 -> 0.1 | Q62: =ROUND(SUMIFS(repasse_ac!$N:$N,repasse_ac!$A:$A,$A62,repasse_ac!$F:$F,$D62,repasse_ac!$I:$I,"TTC PRÉ"),2) -> 1.79 | R62: =ROUND(SUMIFS(repasse_ac!$N:$N,repasse_ac!$A:$A,$A62,repasse_ac!$F:$F,$D62,repasse_ac!$I:$I,"TTC PÓS"),2) -> 1.89 | S62: =R62-Q62 -> 0.1
A63: RR/AC | B63: GEO CO | C63: PET 200 | D63: SLA P200 | E63: =_xlfn.XLOOKUP($D63,depara_repasse!E:E,depara_repasse!K:K) -> 12 | F63: =ROUND(SUMIFS(repasse_ac!$R:$R,repasse_ac!$A:$A,$A63,repasse_ac!$F:$F,$D63,repasse_ac!$I:$I,"TTC PRÉ"),2) -> 1.63 | G63: =ROUND(SUMIFS(repasse_ac!$R:$R,repasse_ac!$A:$A,$A63,repasse_ac!$F:$F,$D63,repasse_ac!$I:$I,"TTC PÓS"),2) -> 1.72 | H63: =G63-F63 -> 0.09 | I63: =(ROUNDDOWN(ROUND(G63*(1+0.2),2)*100/10,0)*10+IF(MOD(ROUND(G63*(1+0.2),2)*100,10)>4,9,-1))/100 -> 2.09 | J63: =ROUND(SUMIFS(repasse_ac!$P:$P,repasse_ac!$A:$A,$A63,repasse_ac!$F:$F,$D63,repasse_ac!$I:$I,"TTC PRÉ"),2) -> 1.59 | K63: =ROUND(SUMIFS(repasse_ac!$P:$P,repasse_ac!$A:$A,$A63,repasse_ac!$F:$F,$D63,repasse_ac!$I:$I,"TTC PÓS"),2) -> 1.67 | L63: =K63-J63 -> 0.08 | M63: =(ROUNDDOWN(ROUND(K63*(1+0.2),2)*100/10,0)*10+IF(MOD(ROUND(K63*(1+0.2),2)*100,10)>4,9,-1))/100 -> 1.99 | N63: =ROUND(SUMIFS(repasse_ac!$J:$J,repasse_ac!$A:$A,$A63,repasse_ac!$F:$F,$D63,repasse_ac!$I:$I,"TTC PRÉ"),2) -> 1.89 | O63: =ROUND(SUMIFS(repasse_ac!$J:$J,repasse_ac!$A:$A,$A63,repasse_ac!$F:$F,$D63,repasse_ac!$I:$I,"TTC PÓS"),2) -> 1.99 | P63: =O63-N63 -> 0.1 | Q63: =ROUND(SUMIFS(repasse_ac!$N:$N,repasse_ac!$A:$A,$A63,repasse_ac!$F:$F,$D63,repasse_ac!$I:$I,"TTC PRÉ"),2) -> 1.79 | R63: =ROUND(SUMIFS(repasse_ac!$N:$N,repasse_ac!$A:$A,$A63,repasse_ac!$F:$F,$D63,repasse_ac!$I:$I,"TTC PÓS"),2) -> 1.89 | S63: =R63-Q63 -> 0.1
A64: RR/AC | B64: GEO CO | C64: PET 200 | D64: SAB P200 | E64: =_xlfn.XLOOKUP($D64,depara_repasse!E:E,depara_repasse!K:K) -> 12 | F64: =ROUND(SUMIFS(repasse_ac!$R:$R,repasse_ac!$A:$A,$A64,repasse_ac!$F:$F,$D64,repasse_ac!$I:$I,"TTC PRÉ"),2) -> 1.63 | G64: =ROUND(SUMIFS(repasse_ac!$R:$R,repasse_ac!$A:$A,$A64,repasse_ac!$F:$F,$D64,repasse_ac!$I:$I,"TTC PÓS"),2) -> 1.72 | H64: =G64-F64 -> 0.09 | I64: =(ROUNDDOWN(ROUND(G64*(1+0.2),2)*100/10,0)*10+IF(MOD(ROUND(G64*(1+0.2),2)*100,10)>4,9,-1))/100 -> 2.09 | J64: =ROUND(SUMIFS(repasse_ac!$P:$P,repasse_ac!$A:$A,$A64,repasse_ac!$F:$F,$D64,repasse_ac!$I:$I,"TTC PRÉ"),2) -> 1.59 | K64: =ROUND(SUMIFS(repasse_ac!$P:$P,repasse_ac!$A:$A,$A64,repasse_ac!$F:$F,$D64,repasse_ac!$I:$I,"TTC PÓS"),2) -> 1.67 | L64: =K64-J64 -> 0.08 | M64: =(ROUNDDOWN(ROUND(K64*(1+0.2),2)*100/10,0)*10+IF(MOD(ROUND(K64*(1+0.2),2)*100,10)>4,9,-1))/100 -> 1.99 | N64: =ROUND(SUMIFS(repasse_ac!$J:$J,repasse_ac!$A:$A,$A64,repasse_ac!$F:$F,$D64,repasse_ac!$I:$I,"TTC PRÉ"),2) -> 1.89 | O64: =ROUND(SUMIFS(repasse_ac!$J:$J,repasse_ac!$A:$A,$A64,repasse_ac!$F:$F,$D64,repasse_ac!$I:$I,"TTC PÓS"),2) -> 1.99 | P64: =O64-N64 -> 0.1 | Q64: =ROUND(SUMIFS(repasse_ac!$N:$N,repasse_ac!$A:$A,$A64,repasse_ac!$F:$F,$D64,repasse_ac!$I:$I,"TTC PRÉ"),2) -> 1.79 | R64: =ROUND(SUMIFS(repasse_ac!$N:$N,repasse_ac!$A:$A,$A64,repasse_ac!$F:$F,$D64,repasse_ac!$I:$I,"TTC PÓS"),2) -> 1.89 | S64: =R64-Q64 -> 0.1
A65: RR/AC | B65: GEO CO | C65: LATA 269 | D65: GCA LT269 | E65: 15 | F65: =ROUND(SUMIFS(repasse_ac!$R:$R,repasse_ac!$A:$A,$A65,repasse_ac!$F:$F,$D65,repasse_ac!$I:$I,"TTC PRÉ"),2) -> 2.19 | G65: =ROUND(SUMIFS(repasse_ac!$R:$R,repasse_ac!$A:$A,$A65,repasse_ac!$F:$F,$D65,repasse_ac!$I:$I,"TTC PÓS"),2) -> 2.19 | H65: =G65-F65 -> 0 | I65: =(ROUNDDOWN(ROUND(G65*(1+0.2),2)*100/10,0)*10+IF(MOD(ROUND(G65*(1+0.2),2)*100,10)>4,9,-1))/100 -> 2.59 | J65: =ROUND(SUMIFS(repasse_ac!$P:$P,repasse_ac!$A:$A,$A65,repasse_ac!$F:$F,$D65,repasse_ac!$I:$I,"TTC PRÉ"),2) -> 2.09 | K65: =ROUND(SUMIFS(repasse_ac!$P:$P,repasse_ac!$A:$A,$A65,repasse_ac!$F:$F,$D65,repasse_ac!$I:$I,"TTC PÓS"),2) -> 2.09 | L65: =K65-J65 -> 0 | M65: =(ROUNDDOWN(ROUND(K65*(1+0.2),2)*100/10,0)*10+IF(MOD(ROUND(K65*(1+0.2),2)*100,10)>4,9,-1))/100 -> 2.49 | N65: =ROUND(SUMIFS(repasse_ac!$J:$J,repasse_ac!$A:$A,$A65,repasse_ac!$F:$F,$D65,repasse_ac!$I:$I,"TTC PRÉ"),2) -> 2.49 | O65: =ROUND(SUMIFS(repasse_ac!$J:$J,repasse_ac!$A:$A,$A65,repasse_ac!$F:$F,$D65,repasse_ac!$I:$I,"TTC PÓS"),2) -> 2.49 | P65: =O65-N65 -> 0 | Q65: =ROUND(SUMIFS(repasse_ac!$N:$N,repasse_ac!$A:$A,$A65,repasse_ac!$F:$F,$D65,repasse_ac!$I:$I,"TTC PRÉ"),2) -> 2.29 | R65: =ROUND(SUMIFS(repasse_ac!$N:$N,repasse_ac!$A:$A,$A65,repasse_ac!$F:$F,$D65,repasse_ac!$I:$I,"TTC PÓS"),2) -> 2.29 | S65: =R65-Q65 -> 0
A66: RR/AC | B66: GEO CO | C66: LATA 269 | D66: PC LT269 | E66: =_xlfn.XLOOKUP($D66,depara_repasse!E:E,depara_repasse!K:K) -> 15 | F66: =ROUND(SUMIFS(repasse_ac!$R:$R,repasse_ac!$A:$A,$A66,repasse_ac!$F:$F,$D66,repasse_ac!$I:$I,"TTC PRÉ"),2) -> 2.19 | G66: =ROUND(SUMIFS(repasse_ac!$R:$R,repasse_ac!$A:$A,$A66,repasse_ac!$F:$F,$D66,repasse_ac!$I:$I,"TTC PÓS"),2) -> 2.19 | H66: =G66-F66 -> 0 | I66: =(ROUNDDOWN(ROUND(G66*(1+0.2),2)*100/10,0)*10+IF(MOD(ROUND(G66*(1+0.2),2)*100,10)>4,9,-1))/100 -> 2.59 | J66: =ROUND(SUMIFS(repasse_ac!$P:$P,repasse_ac!$A:$A,$A66,repasse_ac!$F:$F,$D66,repasse_ac!$I:$I,"TTC PRÉ"),2) -> 2.09 | K66: =ROUND(SUMIFS(repasse_ac!$P:$P,repasse_ac!$A:$A,$A66,repasse_ac!$F:$F,$D66,repasse_ac!$I:$I,"TTC PÓS"),2) -> 2.15 | L66: =K66-J66 -> 0.06 | M66: =(ROUNDDOWN(ROUND(K66*(1+0.2),2)*100/10,0)*10+IF(MOD(ROUND(K66*(1+0.2),2)*100,10)>4,9,-1))/100 -> 2.59 | N66: =ROUND(SUMIFS(repasse_ac!$J:$J,repasse_ac!$A:$A,$A66,repasse_ac!$F:$F,$D66,repasse_ac!$I:$I,"TTC PRÉ"),2) -> 2.49 | O66: =ROUND(SUMIFS(repasse_ac!$J:$J,repasse_ac!$A:$A,$A66,repasse_ac!$F:$F,$D66,repasse_ac!$I:$I,"TTC PÓS"),2) -> 2.59 | P66: =O66-N66 -> 0.1 | Q66: =ROUND(SUMIFS(repasse_ac!$N:$N,repasse_ac!$A:$A,$A66,repasse_ac!$F:$F,$D66,repasse_ac!$I:$I,"TTC PRÉ"),2) -> 2.29 | R66: =ROUND(SUMIFS(repasse_ac!$N:$N,repasse_ac!$A:$A,$A66,repasse_ac!$F:$F,$D66,repasse_ac!$I:$I,"TTC PÓS"),2) -> 2.29 | S66: =R66-Q66 -> 0
A67: RR/AC | B67: GEO CO | C67: LATA 269 | D67: TA LT269 | E67: =_xlfn.XLOOKUP($D67,depara_repasse!E:E,depara_repasse!K:K) -> 15 | F67: =ROUND(SUMIFS(repasse_ac!$R:$R,repasse_ac!$A:$A,$A67,repasse_ac!$F:$F,$D67,repasse_ac!$I:$I,"TTC PRÉ"),2) -> 2.25 | G67: =ROUND(SUMIFS(repasse_ac!$R:$R,repasse_ac!$A:$A,$A67,repasse_ac!$F:$F,$D67,repasse_ac!$I:$I,"TTC PÓS"),2) -> 2.25 | H67: =G67-F67 -> 0 | I67: =(ROUNDDOWN(ROUND(G67*(1+0.2),2)*100/10,0)*10+IF(MOD(ROUND(G67*(1+0.2),2)*100,10)>4,9,-1))/100 -> 2.69 | J67: =ROUND(SUMIFS(repasse_ac!$P:$P,repasse_ac!$A:$A,$A67,repasse_ac!$F:$F,$D67,repasse_ac!$I:$I,"TTC PRÉ"),2) -> 2.09 | K67: =ROUND(SUMIFS(repasse_ac!$P:$P,repasse_ac!$A:$A,$A67,repasse_ac!$F:$F,$D67,repasse_ac!$I:$I,"TTC PÓS"),2) -> 2.17 | L67: =K67-J67 -> 0.08 | M67: =(ROUNDDOWN(ROUND(K67*(1+0.2),2)*100/10,0)*10+IF(MOD(ROUND(K67*(1+0.2),2)*100,10)>4,9,-1))/100 -> 2.59 | N67: =ROUND(SUMIFS(repasse_ac!$J:$J,repasse_ac!$A:$A,$A67,repasse_ac!$F:$F,$D67,repasse_ac!$I:$I,"TTC PRÉ"),2) -> 2.49 | O67: =ROUND(SUMIFS(repasse_ac!$J:$J,repasse_ac!$A:$A,$A67,repasse_ac!$F:$F,$D67,repasse_ac!$I:$I,"TTC PÓS"),2) -> 2.59 | P67: =O67-N67 -> 0.1 | Q67: =ROUND(SUMIFS(repasse_ac!$N:$N,repasse_ac!$A:$A,$A67,repasse_ac!$F:$F,$D67,repasse_ac!$I:$I,"TTC PRÉ"),2) -> 2.49 | R67: =ROUND(SUMIFS(repasse_ac!$N:$N,repasse_ac!$A:$A,$A67,repasse_ac!$F:$F,$D67,repasse_ac!$I:$I,"TTC PÓS"),2) -> 2.49 | S67: =R67-Q67 -> 0
A68: RR/AC | B68: GEO CO | C68: LATA 310 | D68: GCA LT310 | E68: 12 | F68: =ROUND(SUMIFS(repasse_ac!$R:$R,repasse_ac!$A:$A,$A68,repasse_ac!$F:$F,$D68,repasse_ac!$I:$I,"TTC PRÉ"),2) -> 2.09 | G68: =ROUND(SUMIFS(repasse_ac!$R:$R,repasse_ac!$A:$A,$A68,repasse_ac!$F:$F,$D68,repasse_ac!$I:$I,"TTC PÓS"),2) -> 2.09 | H68: =G68-F68 -> 0 | I68: =(ROUNDDOWN(ROUND(G68*(1+0.2),2)*100/10,0)*10+IF(MOD(ROUND(G68*(1+0.2),2)*100,10)>4,9,-1))/100 -> 2.49 | J68: =ROUND(SUMIFS(repasse_ac!$P:$P,repasse_ac!$A:$A,$A68,repasse_ac!$F:$F,$D68,repasse_ac!$I:$I,"TTC PRÉ"),2) -> 1.92 | K68: =ROUND(SUMIFS(repasse_ac!$P:$P,repasse_ac!$A:$A,$A68,repasse_ac!$F:$F,$D68,repasse_ac!$I:$I,"TTC PÓS"),2) -> 1.92 | L68: =K68-J68 -> 0 | M68: =(ROUNDDOWN(ROUND(K68*(1+0.2),2)*100/10,0)*10+IF(MOD(ROUND(K68*(1+0.2),2)*100,10)>4,9,-1))/100 -> 2.39 | N68: =ROUND(SUMIFS(repasse_ac!$J:$J,repasse_ac!$A:$A,$A68,repasse_ac!$F:$F,$D68,repasse_ac!$I:$I,"TTC PRÉ"),2) -> 2.29 | O68: =ROUND(SUMIFS(repasse_ac!$J:$J,repasse_ac!$A:$A,$A68,repasse_ac!$F:$F,$D68,repasse_ac!$I:$I,"TTC PÓS"),2) -> 2.29 | P68: =O68-N68 -> 0 | Q68: =ROUND(SUMIFS(repasse_ac!$N:$N,repasse_ac!$A:$A,$A68,repasse_ac!$F:$F,$D68,repasse_ac!$I:$I,"TTC PRÉ"),2) -> 2.19 | R68: =ROUND(SUMIFS(repasse_ac!$N:$N,repasse_ac!$A:$A,$A68,repasse_ac!$F:$F,$D68,repasse_ac!$I:$I,"TTC PÓS"),2) -> 2.19 | S68: =R68-Q68 -> 0
...

Sheet repasse_concat
A1: GEO | B1: Emb. | C1: SKU | D1: QTD CX | E1: ttv_pre | F1: ttv_pos | G1: pinc | H1: %pinc
A2: GEO CO | B2: PET 200 | C2: GCA P200 | D2: =_xlfn.XLOOKUP($C2,depara_repasse!E:E,depara_repasse!K:K) -> 12 | E2: =ROUND(_xlfn.XLOOKUP($C2,'[1]Canais Estados'!$B:$B,'[1]Canais Estados'!$BJ:$BJ),2) -> 1.34 | F2: =ROUND(_xlfn.XLOOKUP($C2,'[1]Canais Estados'!$B:$B,'[1]Canais Estados'!$BN:$BN),2) -> 1.34 | G2: =F2-E2 -> 0 | H2: =ROUND((F2/E2)-1,4) -> 0
A3: GEO CO | B3: PET 200 | C3: GCAD P200 | D3: =_xlfn.XLOOKUP($C3,depara_repasse!E:E,depara_repasse!K:K) -> 12 | E3: =ROUND(_xlfn.XLOOKUP($C3,'[1]Canais Estados'!$B:$B,'[1]Canais Estados'!$BJ:$BJ),2) -> 1.34 | F3: =ROUND(_xlfn.XLOOKUP($C3,'[1]Canais Estados'!$B:$B,'[1]Canais Estados'!$BN:$BN),2) -> 1.34 | G3: =F3-E3 -> 0 | H3: =ROUND((F3/E3)-1,4) -> 0
A4: GEO CO | B4: PET 200 | C4: PC P200 | D4: =_xlfn.XLOOKUP($C4,depara_repasse!E:E,depara_repasse!K:K) -> 12 | E4: =ROUND(_xlfn.XLOOKUP($C4,'[1]Canais Estados'!$B:$B,'[1]Canais Estados'!$BJ:$BJ),2) -> 1.24 | F4: =ROUND(_xlfn.XLOOKUP($C4,'[1]Canais Estados'!$B:$B,'[1]Canais Estados'!$BN:$BN),2) -> 1.24 | G4: =F4-E4 -> 0 | H4: =ROUND((F4/E4)-1,4) -> 0
A5: GEO CO | B5: PET 200 | C5: SLA P200 | D5: =_xlfn.XLOOKUP($C5,depara_repasse!E:E,depara_repasse!K:K) -> 12 | E5: =ROUND(_xlfn.XLOOKUP($C5,'[1]Canais Estados'!$B:$B,'[1]Canais Estados'!$BJ:$BJ),2) -> 1.24 | F5: =ROUND(_xlfn.XLOOKUP($C5,'[1]Canais Estados'!$B:$B,'[1]Canais Estados'!$BN:$BN),2) -> 1.24 | G5: =F5-E5 -> 0 | H5: =ROUND((F5/E5)-1,4) -> 0
A6: GEO CO | B6: PET 200 | C6: SAB P200 | D6: =_xlfn.XLOOKUP($C6,depara_repasse!E:E,depara_repasse!K:K) -> 12 | E6: =ROUND(_xlfn.XLOOKUP($C6,'[1]Canais Estados'!$B:$B,'[1]Canais Estados'!$BJ:$BJ),2) -> 1.24 | F6: =ROUND(_xlfn.XLOOKUP($C6,'[1]Canais Estados'!$B:$B,'[1]Canais Estados'!$BN:$BN),2) -> 1.24 | G6: =F6-E6 -> 0 | H6: =ROUND((F6/E6)-1,4) -> 0
A7: GEO CO | B7: LATA 269 | C7: GCA LT269 | D7: 15 | E7: =ROUND(_xlfn.XLOOKUP($C7,'[1]Canais Estados'!$B:$B,'[1]Canais Estados'!$BJ:$BJ),2) -> 1.83 | F7: =ROUND(_xlfn.XLOOKUP($C7,'[1]Canais Estados'!$B:$B,'[1]Canais Estados'!$BN:$BN),2) -> 1.83 | G7: =F7-E7 -> 0 | H7: =ROUND((F7/E7)-1,4) -> 0
A8: GEO CO | B8: LATA 269 | C8: PC LT269 | D8: =_xlfn.XLOOKUP($C8,depara_repasse!E:E,depara_repasse!K:K) -> 15 | E8: =ROUND(_xlfn.XLOOKUP($C8,'[1]Canais Estados'!$B:$B,'[1]Canais Estados'!$BJ:$BJ),2) -> 1.83 | F8: =ROUND(_xlfn.XLOOKUP($C8,'[1]Canais Estados'!$B:$B,'[1]Canais Estados'!$BN:$BN),2) -> 1.83 | G8: =F8-E8 -> 0 | H8: =ROUND((F8/E8)-1,4) -> 0
A9: GEO CO | B9: LATA 269 | C9: TA LT269 | D9: =_xlfn.XLOOKUP($C9,depara_repasse!E:E,depara_repasse!K:K) -> 15 | E9: =ROUND(_xlfn.XLOOKUP($C9,'[1]Canais Estados'!$B:$B,'[1]Canais Estados'!$BJ:$BJ),2) -> 1.66 | F9: =ROUND(_xlfn.XLOOKUP($C9,'[1]Canais Estados'!$B:$B,'[1]Canais Estados'!$BN:$BN),2) -> 1.66 | G9: =F9-E9 -> 0 | H9: =ROUND((F9/E9)-1,4) -> 0
A10: GEO CO | B10: LATA 310 | C10: GCA LT310 | D10: 12 | E10: =ROUND(_xlfn.XLOOKUP($C10,'[1]Canais Estados'!$B:$B,'[1]Canais Estados'!$BJ:$BJ),2) -> 1.93 | F10: =ROUND(_xlfn.XLOOKUP($C10,'[1]Canais Estados'!$B:$B,'[1]Canais Estados'!$BN:$BN),2) -> 1.93 | G10: =F10-E10 -> 0 | H10: =ROUND((F10/E10)-1,4) -> 0
A11: GEO CO | B11: LATA 310 | C11: PC LT310 | D11: =_xlfn.XLOOKUP($C11,depara_repasse!E:E,depara_repasse!K:K) -> 15 | E11: =ROUND(_xlfn.XLOOKUP($C11,'[1]Canais Estados'!$B:$B,'[1]Canais Estados'!$BJ:$BJ),2) -> 1.91 | F11: =ROUND(_xlfn.XLOOKUP($C11,'[1]Canais Estados'!$B:$B,'[1]Canais Estados'!$BN:$BN),2) -> 1.91 | G11: =F11-E11 -> 0 | H11: =ROUND((F11/E11)-1,4) -> 0
A12: GEO CO | B12: LATA 350 | C12: GCA LT350 | D12: =_xlfn.XLOOKUP($C12,depara_repasse!E:E,depara_repasse!K:K) -> 12 | E12: =ROUND(_xlfn.XLOOKUP($C12,'[1]Canais Estados'!$B:$B,'[1]Canais Estados'!$BJ:$BJ),2) -> 2.29 | F12: =ROUND(_xlfn.XLOOKUP($C12,'[1]Canais Estados'!$B:$B,'[1]Canais Estados'!$BN:$BN),2) -> 2.36 | G12: =F12-E12 -> 0.07 | H12: =ROUND((F12/E12)-1,4) -> 0.0306
A13: GEO CO | B13: LATA 350 | C13: GCAD LT350 | D13: =_xlfn.XLOOKUP($C13,depara_repasse!E:E,depara_repasse!K:K) -> 12 | E13: =ROUND(_xlfn.XLOOKUP($C13,'[1]Canais Estados'!$B:$B,'[1]Canais Estados'!$BJ:$BJ),2) -> 2.29 | F13: =ROUND(_xlfn.XLOOKUP($C13,'[1]Canais Estados'!$B:$B,'[1]Canais Estados'!$BN:$BN),2) -> 2.37 | G13: =F13-E13 -> 0.08 | H13: =ROUND((F13/E13)-1,4) -> 0.0349
A14: GEO CO | B14: LATA 350 | C14: PC LT350 | D14: =_xlfn.XLOOKUP($C14,depara_repasse!E:E,depara_repasse!K:K) -> 12 | E14: =ROUND(_xlfn.XLOOKUP($C14,'[1]Canais Estados'!$B:$B,'[1]Canais Estados'!$BJ:$BJ),2) -> 2.08 | F14: =ROUND(_xlfn.XLOOKUP($C14,'[1]Canais Estados'!$B:$B,'[1]Canais Estados'!$BN:$BN),2) -> 2.18 | G14: =F14-E14 -> 0.1 | H14: =ROUND((F14/E14)-1,4) -> 0.0481
A15: GEO CO | B15: LATA 350 | C15: SLA LT350 | D15: =_xlfn.XLOOKUP($C15,depara_repasse!E:E,depara_repasse!K:K) -> 12 | E15: =ROUND(_xlfn.XLOOKUP($C15,'[1]Canais Estados'!$B:$B,'[1]Canais Estados'!$BJ:$BJ),2) -> 2.08 | F15: =ROUND(_xlfn.XLOOKUP($C15,'[1]Canais Estados'!$B:$B,'[1]Canais Estados'!$BN:$BN),2) -> 2.18 | G15: =F15-E15 -> 0.1 | H15: =ROUND((F15/E15)-1,4) -> 0.0481
A16: GEO CO | B16: LATA 350 | C16: SAB LT350 | D16: =_xlfn.XLOOKUP($C16,depara_repasse!E:E,depara_repasse!K:K) -> 12 | E16: =ROUND(_xlfn.XLOOKUP($C16,'[1]Canais Estados'!$B:$B,'[1]Canais Estados'!$BJ:$BJ),2) -> 2.08 | F16: =ROUND(_xlfn.XLOOKUP($C16,'[1]Canais Estados'!$B:$B,'[1]Canais Estados'!$BN:$BN),2) -> 2.18 | G16: =F16-E16 -> 0.1 | H16: =ROUND((F16/E16)-1,4) -> 0.0481
A17: GEO CO | B17: LATA 350 | C17: TA LT350 | D17: =_xlfn.XLOOKUP($C17,depara_repasse!E:E,depara_repasse!K:K) -> 12 | E17: =ROUND(_xlfn.XLOOKUP($C17,'[1]Canais Estados'!$B:$B,'[1]Canais Estados'!$BJ:$BJ),2) -> 2.6 | F17: =ROUND(_xlfn.XLOOKUP($C17,'[1]Canais Estados'!$B:$B,'[1]Canais Estados'!$BN:$BN),2) -> 2.65 | G17: =F17-E17 -> 0.05 | H17: =ROUND((F17/E17)-1,4) -> 0.0192
